Workbook

Sheet 1
B2: Empezamo el técnico en la universidad galileo
H3: 1 | K3: =+H3+1 -> 2 | N3: =+K3+1 -> 3 | Q3: =+N3+1 -> 4 | T3: =+Q3+1 -> 5 | W3: =+T3+1 -> 6 | Z3: =+W3+1 -> 7 | AC3: =+Z3+1 -> 8 | AF3: =+AC3+1 -> 9 | AI3: =+AF3+1 -> 10 | AL3: =+AI3+1 -> 11 | AO3: =+AL3+1 -> 12 | AR3: =+AO3+1 -> 13 | AU3: =+AR3+1 -> 14 | AX3: =+AU3+1 -> 15 | BA3: =+AX3+1 -> 16 | BD3: =+BA3+1 -> 17 | BG3: =+BD3+1 -> 18 | BJ3: =+BG3+1 -> 19 | BM3: =+BJ3+1 -> 20 | BP3: =+BM3+1 -> 21 | BS3: =+BP3+1 -> 22 | BV3: =+BS3+1 -> 23 | BY3: =+BV3+1 -> 24 | CB3: =+BY3+1 -> 25 | CE3: =+CB3+1 -> 26 | CH3: =+CE3+1 -> 27 | CK3: =+CH3+1 -> 28 | CN3: =+CK3+1 -> 29 | CQ3: =+CN3+1 -> 30 | CT3: =+CQ3+1 -> 31 | CW3: =+CT3+1 -> 32 | CZ3: =+CW3+1 -> 33 | DC3: =+CZ3+1 -> 34 | DF3: =+DC3+1 -> 35 | DI3: =+DF3+1 -> 36 | DL3: =+DI3+1 -> 37 | DO3: =+DL3+1 -> 38 | DR3: =+DO3+1 -> 39 | DU3: =+DR3+1 -> 40 | DX3: =+DU3+1 -> 41 | EA3: =+DX3+1 -> 42 | ED3: =+EA3+1 -> 43 | EG3: =+ED3+1 -> 44 | EJ3: =+EG3+1 -> 45 | EM3: =+EJ3+1 -> 46
H4: E | I4: Cociente | J4: Residuo | K4: =+VLOOKUP(K3,$A:$B,2,0) -> m | L4: Cociente | M4: Residuo | N4: =+VLOOKUP(N3,$A:$B,2,0) -> p | O4: Cociente | P4: Residuo | Q4: =+VLOOKUP(Q3,$A:$B,2,0) -> e | R4: Cociente | S4: Residuo | T4: =+VLOOKUP(T3,$A:$B,2,0) -> z | U4: Cociente | V4: Residuo | W4: =+VLOOKUP(W3,$A:$B,2,0) -> a | X4: Cociente | Y4: Residuo | Z4: =+VLOOKUP(Z3,$A:$B,2,0) -> m | AA4: Cociente | AB4: Residuo | AC4: =+VLOOKUP(AC3,$A:$B,2,0) -> o | AD4: Cociente | AE4: Residuo | AF4: =+VLOOKUP(AF3,$A:$B,2,0) -> s | AG4: Cociente | AH4: Residuo | AI4: =+VLOOKUP(AI3,$A:$B,2,0) | AJ4: Cociente | AK4: Residuo | AL4: =+VLOOKUP(AL3,$A:$B,2,0) -> e | AM4: Cociente | AN4: Residuo | AO4: =+VLOOKUP(AO3,$A:$B,2,0) -> l | AP4: Cociente | AQ4: Residuo | AR4: =+VLOOKUP(AR3,$A:$B,2,0) | AS4: Cociente | AT4: Residuo | AU4: =+VLOOKUP(AU3,$A:$B,2,0) -> t | AV4: Cociente | AW4: Residuo | AX4: =+VLOOKUP(AX3,$A:$B,2,0) -> e | AY4: Cociente | AZ4: Residuo | BA4: =+VLOOKUP(BA3,$A:$B,2,0) -> c | BB4: Cociente | BC4: Residuo | BD4: =+VLOOKUP(BD3,$A:$B,2,0) -> n | BE4: Cociente | BF4: Residuo | BG4: =+VLOOKUP(BG3,$A:$B,2,0) -> i | BH4: Cociente | BI4: Residuo | BJ4: =+VLOOKUP(BJ3,$A:$B,2,0) -> c | BK4: Cociente | BL4: Residuo | BM4: =+VLOOKUP(BM3,$A:$B,2,0) -> o | BN4: Cociente | BO4: Residuo | BP4: =+VLOOKUP(BP3,$A:$B,2,0) | BQ4: Cociente | BR4: Residuo | BS4: =+VLOOKUP(BS3,$A:$B,2,0) -> e | BT4: Cociente | BU4: Residuo | BV4: =+VLOOKUP(BV3,$A:$B,2,0) -> n | BW4: Cociente | BX4: Residuo | BY4: =+VLOOKUP(BY3,$A:$B,2,0) | BZ4: Cociente | CA4: Residuo | CB4: =+VLOOKUP(CB3,$A:$B,2,0) -> l | CC4: Cociente | CD4: Residuo | CE4: =+VLOOKUP(CE3,$A:$B,2,0) -> a | CF4: Cociente | CG4: Residuo | CH4: =+VLOOKUP(CH3,$A:$B,2,0) | CI4: Cociente | CJ4: Residuo | CK4: =+VLOOKUP(CK3,$A:$B,2,0) -> u | CL4: Cociente | CM4: Residuo | CN4: =+VLOOKUP(CN3,$A:$B,2,0) -> n | CO4: Cociente | CP4: Residuo | CQ4: =+VLOOKUP(CQ3,$A:$B,2,0) -> i | CR4: Cociente | CS4: Residuo | CT4: =+VLOOKUP(CT3,$A:$B,2,0) -> v | CU4: Cociente | CV4: Residuo | CW4: =+VLOOKUP(CW3,$A:$B,2,0) -> e | CX4: Cociente | CY4: Residuo | CZ4: =+VLOOKUP(CZ3,$A:$B,2,0) -> r | DA4: Cociente | DB4: Residuo | DC4: =+VLOOKUP(DC3,$A:$B,2,0) -> s | DD4: Cociente | DE4: Residuo | DF4: =+VLOOKUP(DF3,$A:$B,2,0) -> i | DG4: Cociente | DH4: Residuo | DI4: =+VLOOKUP(DI3,$A:$B,2,0) -> d | DJ4: Cociente | DK4: Residuo | DL4: =+VLOOKUP(DL3,$A:$B,2,0) -> a | DM4: Cociente | DN4: Residuo | DO4: =+VLOOKUP(DO3,$A:$B,2,0) -> d | DP4: Cociente | DQ4: Residuo | DR4: =+VLOOKUP(DR3,$A:$B,2,0) | DS4: Cociente | DT4: Residuo | DU4: =+VLOOKUP(DU3,$A:$B,2,0) -> g | DV4: Cociente | DW4: Residuo | DX4: =+VLOOKUP(DX3,$A:$B,2,0) -> a | DY4: Cociente | DZ4: Residuo | EA4: =+VLOOKUP(EA3,$A:$B,2,0) -> l | EB4: Cociente | EC4: Residuo | ED4: =+VLOOKUP(ED3,$A:$B,2,0) -> i | EE4: Cociente | EF4: Residuo | EG4: =+VLOOKUP(EG3,$A:$B,2,0) -> l | EH4: Cociente | EI4: Residuo | EJ4: =+VLOOKUP(EJ3,$A:$B,2,0) -> e | EK4: Cociente | EL4: Residuo | EM4: =+VLOOKUP(EM3,$A:$B,2,0) -> o | EN4: Cociente | EO4: Residuo
A5: 1 | B5: E | C5: =+VLOOKUP(B5,Hoja2!$G:$K,5,0) -> 69 | D5: 69 | E5: 01000101 | F5: =+E5 -> 01000101 | H5: 69 | I5: =INT(H5/2) -> 34 | J5: =MOD(H5,2) -> 1 | K5: =+VLOOKUP(K4,$B:$D,3,0) -> 109 | L5: =INT(K5/2) -> 54 | M5: =MOD(K5,2) -> 1 | N5: =+VLOOKUP(N4,$B:$D,3,0) -> 112 | O5: =INT(N5/2) -> 56 | P5: =MOD(N5,2) -> 0 | Q5: 101 | R5: =INT(Q5/2) -> 50 | S5: =MOD(Q5,2) -> 1 | T5: =+VLOOKUP(T4,$B:$D,3,0) -> 122 | U5: =INT(T5/2) -> 61 | V5: =MOD(T5,2) -> 0 | W5: =+VLOOKUP(W4,$B:$D,3,0) -> 97 | X5: =INT(W5/2) -> 48 | Y5: =MOD(W5,2) -> 1 | Z5: =+VLOOKUP(Z4,$B:$D,3,0) -> 109 | AA5: =INT(Z5/2) -> 54 | AB5: =MOD(Z5,2) -> 1 | AC5: =+VLOOKUP(AC4,$B:$D,3,0) -> 111 | AD5: =INT(AC5/2) -> 55 | AE5: =MOD(AC5,2) -> 1 | AF5: =+VLOOKUP(AF4,$B:$D,3,0) -> 115 | AG5: =INT(AF5/2) -> 57 | AH5: =MOD(AF5,2) -> 1 | AI5: =+VLOOKUP(AI4,$B:$D,3,0) -> 32 | AJ5: =INT(AI5/2) -> 16 | AK5: =MOD(AI5,2) -> 0 | AL5: 101 | AM5: =INT(AL5/2) -> 50 | AN5: =MOD(AL5,2) -> 1 | AO5: =+VLOOKUP(AO4,$B:$D,3,0) -> 108 | AP5: =INT(AO5/2) -> 54 | AQ5: =MOD(AO5,2) -> 0 | AR5: =+VLOOKUP(AR4,$B:$D,3,0) -> 32 | AS5: =INT(AR5/2) -> 16 | AT5: =MOD(AR5,2) -> 0 | AU5: =+VLOOKUP(AU4,$B:$D,3,0) -> 116 | AV5: =INT(AU5/2) -> 58 | AW5: =MOD(AU5,2) -> 0 | AX5: 101 | AY5: =INT(AX5/2) -> 50 | AZ5: =MOD(AX5,2) -> 1 | BA5: =+VLOOKUP(BA4,$B:$D,3,0) -> 99 | BB5: =INT(BA5/2) -> 49 | BC5: =MOD(BA5,2) -> 1 | BD5: =+VLOOKUP(BD4,$B:$D,3,0) -> 110 | BE5: =INT(BD5/2) -> 55 | BF5: =MOD(BD5,2) -> 0 | BG5: =+VLOOKUP(BG4,$B:$D,3,0) -> 105 | BH5: =INT(BG5/2) -> 52 | BI5: =MOD(BG5,2) -> 1 | BJ5: =+VLOOKUP(BJ4,$B:$D,3,0) -> 99 | BK5: =INT(BJ5/2) -> 49 | BL5: =MOD(BJ5,2) -> 1 | BM5: =+VLOOKUP(BM4,$B:$D,3,0) -> 111 | BN5: =INT(BM5/2) -> 55 | BO5: =MOD(BM5,2) -> 1 | BP5: =+VLOOKUP(BP4,$B:$D,3,0) -> 32 | BQ5: =INT(BP5/2) -> 16 | BR5: =MOD(BP5,2) -> 0 | BS5: 101 | BT5: =INT(BS5/2) -> 50 | BU5: =MOD(BS5,2) -> 1 | BV5: =+VLOOKUP(BV4,$B:$D,3,0) -> 110 | BW5: =INT(BV5/2) -> 55 | BX5: =MOD(BV5,2) -> 0 | BY5: =+VLOOKUP(BY4,$B:$D,3,0) -> 32 | BZ5: =INT(BY5/2) -> 16 | CA5: =MOD(BY5,2) -> 0 | CB5: =+VLOOKUP(CB4,$B:$D,3,0) -> 108 | CC5: =INT(CB5/2) -> 54 | CD5: =MOD(CB5,2) -> 0 | CE5: =+VLOOKUP(CE4,$B:$D,3,0) -> 97 | CF5: =INT(CE5/2) -> 48 | CG5: =MOD(CE5,2) -> 1 | CH5: =+VLOOKUP(CH4,$B:$D,3,0) -> 32 | CI5: =INT(CH5/2) -> 16 | CJ5: =MOD(CH5,2) -> 0 | CK5: =+VLOOKUP(CK4,$B:$D,3,0) -> 117 | CL5: =INT(CK5/2) -> 58 | CM5: =MOD(CK5,2) -> 1 | CN5: =+VLOOKUP(CN4,$B:$D,3,0) -> 110 | CO5: =INT(CN5/2) -> 55 | CP5: =MOD(CN5,2) -> 0 | CQ5: =+VLOOKUP(CQ4,$B:$D,3,0) -> 105 | CR5: =INT(CQ5/2) -> 52 | CS5: =MOD(CQ5,2) -> 1 | CT5: =+VLOOKUP(CT4,$B:$D,3,0) -> 118 | CU5: =INT(CT5/2) -> 59 | CV5: =MOD(CT5,2) -> 0 | CW5: 101 | CX5: =INT(CW5/2) -> 50 | CY5: =MOD(CW5,2) -> 1 | CZ5: =+VLOOKUP(CZ4,$B:$D,3,0) -> 114 | DA5: =INT(CZ5/2) -> 57 | DB5: =MOD(CZ5,2) -> 0 | DC5: =+VLOOKUP(DC4,$B:$D,3,0) -> 115 | DD5: =INT(DC5/2) -> 57 | DE5: =MOD(DC5,2) -> 1 | DF5: =+VLOOKUP(DF4,$B:$D,3,0) -> 105 | DG5: =INT(DF5/2) -> 52 | DH5: =MOD(DF5,2) -> 1 | DI5: =+VLOOKUP(DI4,$B:$D,3,0) -> 100 | DJ5: =INT(DI5/2) -> 50 | DK5: =MOD(DI5,2) -> 0 | DL5: =+VLOOKUP(DL4,$B:$D,3,0) -> 97 | DM5: =INT(DL5/2) -> 48 | DN5: =MOD(DL5,2) -> 1 | DO5: =+VLOOKUP(DO4,$B:$D,3,0) -> 100 | DP5: =INT(DO5/2) -> 50 | DQ5: =MOD(DO5,2) -> 0 | DR5: =+VLOOKUP(DR4,$B:$D,3,0) -> 32 | DS5: =INT(DR5/2) -> 16 | DT5: =MOD(DR5,2) -> 0 | DU5: =+VLOOKUP(DU4,$B:$D,3,0) -> 103 | DV5: =INT(DU5/2) -> 51 | DW5: =MOD(DU5,2) -> 1 | DX5: =+VLOOKUP(DX4,$B:$D,3,0) -> 97 | DY5: =INT(DX5/2) -> 48 | DZ5: =MOD(DX5,2) -> 1 | EA5: =+VLOOKUP(EA4,$B:$D,3,0) -> 108 | EB5: =INT(EA5/2) -> 54 | EC5: =MOD(EA5,2) -> 0 | ED5: =+VLOOKUP(ED4,$B:$D,3,0) -> 105 | EE5: =INT(ED5/2) -> 52 | EF5: =MOD(ED5,2) -> 1 | EG5: =+VLOOKUP(EG4,$B:$D,3,0) -> 108 | EH5: =INT(EG5/2) -> 54 | EI5: =MOD(EG5,2) -> 0 | EJ5: 101 | EK5: =INT(EJ5/2) -> 50 | EL5: =MOD(EJ5,2) -> 1 | EM5: =+VLOOKUP(EM4,$B:$D,3,0) -> 111 | EN5: =INT(EM5/2) -> 55 | EO5: =MOD(EM5,2) -> 1
A6: =+A5+1 -> 2 | B6: m | C6: =+VLOOKUP(B6,Hoja2!$A:$E,5,0) -> 109 | D6: 109 | E6: 01101101 | F6: =+F5&$F$4&E6 -> 01000101 01101101 | H6: =+I5 -> 34 | I6: =INT(H6/2) -> 17 | J6: =MOD(H6,2) -> 0 | K6: =+L5 -> 54 | L6: =INT(K6/2) -> 27 | M6: =MOD(K6,2) -> 0 | N6: =+O5 -> 56 | O6: =INT(N6/2) -> 28 | P6: =MOD(N6,2) -> 0 | Q6: =+R5 -> 50 | R6: =INT(Q6/2) -> 25 | S6: =MOD(Q6,2) -> 0 | T6: =+U5 -> 61 | U6: =INT(T6/2) -> 30 | V6: =MOD(T6,2) -> 1 | W6: =+X5 -> 48 | X6: =INT(W6/2) -> 24 | Y6: =MOD(W6,2) -> 0 | Z6: =+AA5 -> 54 | AA6: =INT(Z6/2) -> 27 | AB6: =MOD(Z6,2) -> 0 | AC6: =+AD5 -> 55 | AD6: =INT(AC6/2) -> 27 | AE6: =MOD(AC6,2) -> 1 | AF6: =+AG5 -> 57 | AG6: =INT(AF6/2) -> 28 | AH6: =MOD(AF6,2) -> 1 | AI6: =+AJ5 -> 16 | AJ6: =INT(AI6/2) -> 8 | AK6: =MOD(AI6,2) -> 0 | AL6: =+AM5 -> 50 | AM6: =INT(AL6/2) -> 25 | AN6: =MOD(AL6,2) -> 0 | AO6: =+AP5 -> 54 | AP6: =INT(AO6/2) -> 27 | AQ6: =MOD(AO6,2) -> 0 | AR6: =+AS5 -> 16 | AS6: =INT(AR6/2) -> 8 | AT6: =MOD(AR6,2) -> 0 | AU6: =+AV5 -> 58 | AV6: =INT(AU6/2) -> 29 | AW6: =MOD(AU6,2) -> 0 | AX6: =+AY5 -> 50 | AY6: =INT(AX6/2) -> 25 | AZ6: =MOD(AX6,2) -> 0 | BA6: =+BB5 -> 49 | BB6: =INT(BA6/2) -> 24 | BC6: =MOD(BA6,2) -> 1 | BD6: =+BE5 -> 55 | BE6: =INT(BD6/2) -> 27 | BF6: =MOD(BD6,2) -> 1 | BG6: =+BH5 -> 52 | BH6: =INT(BG6/2) -> 26 | BI6: =MOD(BG6,2) -> 0 | BJ6: =+BK5 -> 49 | BK6: =INT(BJ6/2) -> 24 | BL6: =MOD(BJ6,2) -> 1 | BM6: =+BN5 -> 55 | BN6: =INT(BM6/2) -> 27 | BO6: =MOD(BM6,2) -> 1 | BP6: =+BQ5 -> 16 | BQ6: =INT(BP6/2) -> 8 | BR6: =MOD(BP6,2) -> 0 | BS6: =+BT5 -> 50 | BT6: =INT(BS6/2) -> 25 | BU6: =MOD(BS6,2) -> 0 | BV6: =+BW5 -> 55 | BW6: =INT(BV6/2) -> 27 | BX6: =MOD(BV6,2) -> 1 | BY6: =+BZ5 -> 16 | BZ6: =INT(BY6/2) -> 8 | CA6: =MOD(BY6,2) -> 0 | CB6: =+CC5 -> 54 | CC6: =INT(CB6/2) -> 27 | CD6: =MOD(CB6,2) -> 0 | CE6: =+CF5 -> 48 | CF6: =INT(CE6/2) -> 24 | CG6: =MOD(CE6,2) -> 0 | CH6: =+CI5 -> 16 | CI6: =INT(CH6/2) -> 8 | CJ6: =MOD(CH6,2) -> 0 | CK6: =+CL5 -> 58 | CL6: =INT(CK6/2) -> 29 | CM6: =MOD(CK6,2) -> 0 | CN6: =+CO5 -> 55 | CO6: =INT(CN6/2) -> 27 | CP6: =MOD(CN6,2) -> 1 | CQ6: =+CR5 -> 52 | CR6: =INT(CQ6/2) -> 26 | CS6: =MOD(CQ6,2) -> 0 | CT6: =+CU5 -> 59 | CU6: =INT(CT6/2) -> 29 | CV6: =MOD(CT6,2) -> 1 | CW6: =+CX5 -> 50 | CX6: =INT(CW6/2) -> 25 | CY6: =MOD(CW6,2) -> 0 | CZ6: =+DA5 -> 57 | DA6: =INT(CZ6/2) -> 28 | DB6: =MOD(CZ6,2) -> 1 | DC6: =+DD5 -> 57 | DD6: =INT(DC6/2) -> 28 | DE6: =MOD(DC6,2) -> 1 | DF6: =+DG5 -> 52 | DG6: =INT(DF6/2) -> 26 | DH6: =MOD(DF6,2) -> 0 | DI6: =+DJ5 -> 50 | DJ6: =INT(DI6/2) -> 25 | DK6: =MOD(DI6,2) -> 0 | DL6: =+DM5 -> 48 | DM6: =INT(DL6/2) -> 24 | DN6: =MOD(DL6,2) -> 0 | DO6: =+DP5 -> 50 | DP6: =INT(DO6/2) -> 25 | DQ6: =MOD(DO6,2) -> 0 | DR6: =+DS5 -> 16 | DS6: =INT(DR6/2) -> 8 | DT6: =MOD(DR6,2) -> 0 | DU6: =+DV5 -> 51 | DV6: =INT(DU6/2) -> 25 | DW6: =MOD(DU6,2) -> 1 | DX6: =+DY5 -> 48 | DY6: =INT(DX6/2) -> 24 | DZ6: =MOD(DX6,2) -> 0 | EA6: =+EB5 -> 54 | EB6: =INT(EA6/2) -> 27 | EC6: =MOD(EA6,2) -> 0 | ED6: =+EE5 -> 52 | EE6: =INT(ED6/2) -> 26 | EF6: =MOD(ED6,2) -> 0 | EG6: =+EH5 -> 54 | EH6: =INT(EG6/2) -> 27 | EI6: =MOD(EG6,2) -> 0 | EJ6: =+EK5 -> 50 | EK6: =INT(EJ6/2) -> 25 | EL6: =MOD(EJ6,2) -> 0 | EM6: =+EN5 -> 55 | EN6: =INT(EM6/2) -> 27 | EO6: =MOD(EM6,2) -> 1
A7: =+A6+1 -> 3 | B7: p | C7: =+VLOOKUP(B7,Hoja2!$A:$E,5,0) -> 112 | D7: 112 | E7: 01110000 | F7: =+F6&$F$4&E7 -> 01000101 01101101 01110000 | H7: =+I6 -> 17 | I7: =INT(H7/2) -> 8 | J7: =MOD(H7,2) -> 1 | K7: =+L6 -> 27 | L7: =INT(K7/2) -> 13 | M7: =MOD(K7,2) -> 1 | N7: =+O6 -> 28 | O7: =INT(N7/2) -> 14 | P7: =MOD(N7,2) -> 0 | Q7: =+R6 -> 25 | R7: =INT(Q7/2) -> 12 | S7: =MOD(Q7,2) -> 1 | T7: =+U6 -> 30 | U7: =INT(T7/2) -> 15 | V7: =MOD(T7,2) -> 0 | W7: =+X6 -> 24 | X7: =INT(W7/2) -> 12 | Y7: =MOD(W7,2) -> 0 | Z7: =+AA6 -> 27 | AA7: =INT(Z7/2) -> 13 | AB7: =MOD(Z7,2) -> 1 | AC7: =+AD6 -> 27 | AD7: =INT(AC7/2) -> 13 | AE7: =MOD(AC7,2) -> 1 | AF7: =+AG6 -> 28 | AG7: =INT(AF7/2) -> 14 | AH7: =MOD(AF7,2) -> 0 | AI7: =+AJ6 -> 8 | AJ7: =INT(AI7/2) -> 4 | AK7: =MOD(AI7,2) -> 0 | AL7: =+AM6 -> 25 | AM7: =INT(AL7/2) -> 12 | AN7: =MOD(AL7,2) -> 1 | AO7: =+AP6 -> 27 | AP7: =INT(AO7/2) -> 13 | AQ7: =MOD(AO7,2) -> 1 | AR7: =+AS6 -> 8 | AS7: =INT(AR7/2) -> 4 | AT7: =MOD(AR7,2) -> 0 | AU7: =+AV6 -> 29 | AV7: =INT(AU7/2) -> 14 | AW7: =MOD(AU7,2) -> 1 | AX7: =+AY6 -> 25 | AY7: =INT(AX7/2) -> 12 | AZ7: =MOD(AX7,2) -> 1 | BA7: =+BB6 -> 24 | BB7: =INT(BA7/2) -> 12 | BC7: =MOD(BA7,2) -> 0 | BD7: =+BE6 -> 27 | BE7: =INT(BD7/2) -> 13 | BF7: =MOD(BD7,2) -> 1 | BG7: =+BH6 -> 26 | BH7: =INT(BG7/2) -> 13 | BI7: =MOD(BG7,2) -> 0 | BJ7: =+BK6 -> 24 | BK7: =INT(BJ7/2) -> 12 | BL7: =MOD(BJ7,2) -> 0 | BM7: =+BN6 -> 27 | BN7: =INT(BM7/2) -> 13 | BO7: =MOD(BM7,2) -> 1 | BP7: =+BQ6 -> 8 | BQ7: =INT(BP7/2) -> 4 | BR7: =MOD(BP7,2) -> 0 | BS7: =+BT6 -> 25 | BT7: =INT(BS7/2) -> 12 | BU7: =MOD(BS7,2) -> 1 | BV7: =+BW6 -> 27 | BW7: =INT(BV7/2) -> 13 | BX7: =MOD(BV7,2) -> 1 | BY7: =+BZ6 -> 8 | BZ7: =INT(BY7/2) -> 4 | CA7: =MOD(BY7,2) -> 0 | CB7: =+CC6 -> 27 | CC7: =INT(CB7/2) -> 13 | CD7: =MOD(CB7,2) -> 1 | CE7: =+CF6 -> 24 | CF7: =INT(CE7/2) -> 12 | CG7: =MOD(CE7,2) -> 0 | CH7: =+CI6 -> 8 | CI7: =INT(CH7/2) -> 4 | CJ7: =MOD(CH7,2) -> 0 | CK7: =+CL6 -> 29 | CL7: =INT(CK7/2) -> 14 | CM7: =MOD(CK7,2) -> 1 | CN7: =+CO6 -> 27 | CO7: =INT(CN7/2) -> 13 | CP7: =MOD(CN7,2) -> 1 | CQ7: =+CR6 -> 26 | CR7: =INT(CQ7/2) -> 13 | CS7: =MOD(CQ7,2) -> 0 | CT7: =+CU6 -> 29 | CU7: =INT(CT7/2) -> 14 | CV7: =MOD(CT7,2) -> 1 | CW7: =+CX6 -> 25 | CX7: =INT(CW7/2) -> 12 | CY7: =MOD(CW7,2) -> 1 | CZ7: =+DA6 -> 28 | DA7: =INT(CZ7/2) -> 14 | DB7: =MOD(CZ7,2) -> 0 | DC7: =+DD6 -> 28 | DD7: =INT(DC7/2) -> 14 | DE7: =MOD(DC7,2) -> 0 | DF7: =+DG6 -> 26 | DG7: =INT(DF7/2) -> 13 | DH7: =MOD(DF7,2) -> 0 | DI7: =+DJ6 -> 25 | DJ7: =INT(DI7/2) -> 12 | DK7: =MOD(DI7,2) -> 1 | DL7: =+DM6 -> 24 | DM7: =INT(DL7/2) -> 12 | DN7: =MOD(DL7,2) -> 0 | DO7: =+DP6 -> 25 | DP7: =INT(DO7/2) -> 12 | DQ7: =MOD(DO7,2) -> 1 | DR7: =+DS6 -> 8 | DS7: =INT(DR7/2) -> 4 | DT7: =MOD(DR7,2) -> 0 | DU7: =+DV6 -> 25 | DV7: =INT(DU7/2) -> 12 | DW7: =MOD(DU7,2) -> 1 | DX7: =+DY6 -> 24 | DY7: =INT(DX7/2) -> 12 | DZ7: =MOD(DX7,2) -> 0 | EA7: =+EB6 -> 27 | EB7: =INT(EA7/2) -> 13 | EC7: =MOD(EA7,2) -> 1 | ED7: =+EE6 -> 26 | EE7: =INT(ED7/2) -> 13 | EF7: =MOD(ED7,2) -> 0 | EG7: =+EH6 -> 27 | EH7: =INT(EG7/2) -> 13 | EI7: =MOD(EG7,2) -> 1 | EJ7: =+EK6 -> 25 | EK7: =INT(EJ7/2) -> 12 | EL7: =MOD(EJ7,2) -> 1 | EM7: =+EN6 -> 27 | EN7: =INT(EM7/2) -> 13 | EO7: =MOD(EM7,2) -> 1
A8: =+A7+1 -> 4 | B8: e | C8: =+VLOOKUP(B8,Hoja2!$A:$E,5,0) -> 101 | D8: 101 | E8: 01100101 | F8: =+F7&$F$4&E8 -> 01000101 01101101 01110000 01100101 | H8: =+I7 -> 8 | I8: =INT(H8/2) -> 4 | J8: =MOD(H8,2) -> 0 | K8: =+L7 -> 13 | L8: =INT(K8/2) -> 6 | M8: =MOD(K8,2) -> 1 | N8: =+O7 -> 14 | O8: =INT(N8/2) -> 7 | P8: =MOD(N8,2) -> 0 | Q8: =+R7 -> 12 | R8: =INT(Q8/2) -> 6 | S8: =MOD(Q8,2) -> 0 | T8: =+U7 -> 15 | U8: =INT(T8/2) -> 7 | V8: =MOD(T8,2) -> 1 | W8: =+X7 -> 12 | X8: =INT(W8/2) -> 6 | Y8: =MOD(W8,2) -> 0 | Z8: =+AA7 -> 13 | AA8: =INT(Z8/2) -> 6 | AB8: =MOD(Z8,2) -> 1 | AC8: =+AD7 -> 13 | AD8: =INT(AC8/2) -> 6 | AE8: =MOD(AC8,2) -> 1 | AF8: =+AG7 -> 14 | AG8: =INT(AF8/2) -> 7 | AH8: =MOD(AF8,2) -> 0 | AI8: =+AJ7 -> 4 | AJ8: =INT(AI8/2) -> 2 | AK8: =MOD(AI8,2) -> 0 | AL8: =+AM7 -> 12 | AM8: =INT(AL8/2) -> 6 | AN8: =MOD(AL8,2) -> 0 | AO8: =+AP7 -> 13 | AP8: =INT(AO8/2) -> 6 | AQ8: =MOD(AO8,2) -> 1 | AR8: =+AS7 -> 4 | AS8: =INT(AR8/2) -> 2 | AT8: =MOD(AR8,2) -> 0 | AU8: =+AV7 -> 14 | AV8: =INT(AU8/2) -> 7 | AW8: =MOD(AU8,2) -> 0 | AX8: =+AY7 -> 12 | AY8: =INT(AX8/2) -> 6 | AZ8: =MOD(AX8,2) -> 0 | BA8: =+BB7 -> 12 | BB8: =INT(BA8/2) -> 6 | BC8: =MOD(BA8,2) -> 0 | BD8: =+BE7 -> 13 | BE8: =INT(BD8/2) -> 6 | BF8: =MOD(BD8,2) -> 1 | BG8: =+BH7 -> 13 | BH8: =INT(BG8/2) -> 6 | BI8: =MOD(BG8,2) -> 1 | BJ8: =+BK7 -> 12 | BK8: =INT(BJ8/2) -> 6 | BL8: =MOD(BJ8,2) -> 0 | BM8: =+BN7 -> 13 | BN8: =INT(BM8/2) -> 6 | BO8: =MOD(BM8,2) -> 1 | BP8: =+BQ7 -> 4 | BQ8: =INT(BP8/2) -> 2 | BR8: =MOD(BP8,2) -> 0 | BS8: =+BT7 -> 12 | BT8: =INT(BS8/2) -> 6 | BU8: =MOD(BS8,2) -> 0 | BV8: =+BW7 -> 13 | BW8: =INT(BV8/2) -> 6 | BX8: =MOD(BV8,2) -> 1 | BY8: =+BZ7 -> 4 | BZ8: =INT(BY8/2) -> 2 | CA8: =MOD(BY8,2) -> 0 | CB8: =+CC7 -> 13 | CC8: =INT(CB8/2) -> 6 | CD8: =MOD(CB8,2) -> 1 | CE8: =+CF7 -> 12 | CF8: =INT(CE8/2) -> 6 | CG8: =MOD(CE8,2) -> 0 | CH8: =+CI7 -> 4 | CI8: =INT(CH8/2) -> 2 | CJ8: =MOD(CH8,2) -> 0 | CK8: =+CL7 -> 14 | CL8: =INT(CK8/2) -> 7 | CM8: =MOD(CK8,2) -> 0 | CN8: =+CO7 -> 13 | CO8: =INT(CN8/2) -> 6 | CP8: =MOD(CN8,2) -> 1 | CQ8: =+CR7 -> 13 | CR8: =INT(CQ8/2) -> 6 | CS8: =MOD(CQ8,2) -> 1 | CT8: =+CU7 -> 14 | CU8: =INT(CT8/2) -> 7 | CV8: =MOD(CT8,2) -> 0 | CW8: =+CX7 -> 12 | CX8: =INT(CW8/2) -> 6 | CY8: =MOD(CW8,2) -> 0 | CZ8: =+DA7 -> 14 | DA8: =INT(CZ8/2) -> 7 | DB8: =MOD(CZ8,2) -> 0 | DC8: =+DD7 -> 14 | DD8: =INT(DC8/2) -> 7 | DE8: =MOD(DC8,2) -> 0 | DF8: =+DG7 -> 13 | DG8: =INT(DF8/2) -> 6 | DH8: =MOD(DF8,2) -> 1 | DI8: =+DJ7 -> 12 | DJ8: =INT(DI8/2) -> 6 | DK8: =MOD(DI8,2) -> 0 | DL8: =+DM7 -> 12 | DM8: =INT(DL8/2) -> 6 | DN8: =MOD(DL8,2) -> 0 | DO8: =+DP7 -> 12 | DP8: =INT(DO8/2) -> 6 | DQ8: =MOD(DO8,2) -> 0 | DR8: =+DS7 -> 4 | DS8: =INT(DR8/2) -> 2 | DT8: =MOD(DR8,2) -> 0 | DU8: =+DV7 -> 12 | DV8: =INT(DU8/2) -> 6 | DW8: =MOD(DU8,2) -> 0 | DX8: =+DY7 -> 12 | DY8: =INT(DX8/2) -> 6 | DZ8: =MOD(DX8,2) -> 0 | EA8: =+EB7 -> 13 | EB8: =INT(EA8/2) -> 6 | EC8: =MOD(EA8,2) -> 1 | ED8: =+EE7 -> 13 | EE8: =INT(ED8/2) -> 6 | EF8: =MOD(ED8,2) -> 1 | EG8: =+EH7 -> 13 | EH8: =INT(EG8/2) -> 6 | EI8: =MOD(EG8,2) -> 1 | EJ8: =+EK7 -> 12 | EK8: =INT(EJ8/2) -> 6 | EL8: =MOD(EJ8,2) -> 0 | EM8: =+EN7 -> 13 | EN8: =INT(EM8/2) -> 6 | EO8: =MOD(EM8,2) -> 1
A9: =+A8+1 -> 5 | B9: z | C9: =+VLOOKUP(B9,Hoja2!$A:$E,5,0) -> 122 | D9: 122 | E9: 01111010 | F9: =+F8&$F$4&E9 -> 01000101 01101101 01110000 01100101 01111010 | H9: =+I8 -> 4 | I9: =INT(H9/2) -> 2 | J9: =MOD(H9,2) -> 0 | K9: =+L8 -> 6 | L9: =INT(K9/2) -> 3 | M9: =MOD(K9,2) -> 0 | N9: =+O8 -> 7 | O9: =INT(N9/2) -> 3 | P9: =MOD(N9,2) -> 1 | Q9: =+R8 -> 6 | R9: =INT(Q9/2) -> 3 | S9: =MOD(Q9,2) -> 0 | T9: =+U8 -> 7 | U9: =INT(T9/2) -> 3 | V9: =MOD(T9,2) -> 1 | W9: =+X8 -> 6 | X9: =INT(W9/2) -> 3 | Y9: =MOD(W9,2) -> 0 | Z9: =+AA8 -> 6 | AA9: =INT(Z9/2) -> 3 | AB9: =MOD(Z9,2) -> 0 | AC9: =+AD8 -> 6 | AD9: =INT(AC9/2) -> 3 | AE9: =MOD(AC9,2) -> 0 | AF9: =+AG8 -> 7 | AG9: =INT(AF9/2) -> 3 | AH9: =MOD(AF9,2) -> 1 | AI9: =+AJ8 -> 2 | AJ9: =INT(AI9/2) -> 1 | AK9: =MOD(AI9,2) -> 0 | AL9: =+AM8 -> 6 | AM9: =INT(AL9/2) -> 3 | AN9: =MOD(AL9,2) -> 0 | AO9: =+AP8 -> 6 | AP9: =INT(AO9/2) -> 3 | AQ9: =MOD(AO9,2) -> 0 | AR9: =+AS8 -> 2 | AS9: =INT(AR9/2) -> 1 | AT9: =MOD(AR9,2) -> 0 | AU9: =+AV8 -> 7 | AV9: =INT(AU9/2) -> 3 | AW9: =MOD(AU9,2) -> 1 | AX9: =+AY8 -> 6 | AY9: =INT(AX9/2) -> 3 | AZ9: =MOD(AX9,2) -> 0 | BA9: =+BB8 -> 6 | BB9: =INT(BA9/2) -> 3 | BC9: =MOD(BA9,2) -> 0 | BD9: =+BE8 -> 6 | BE9: =INT(BD9/2) -> 3 | BF9: =MOD(BD9,2) -> 0 | BG9: =+BH8 -> 6 | BH9: =INT(BG9/2) -> 3 | BI9: =MOD(BG9,2) -> 0 | BJ9: =+BK8 -> 6 | BK9: =INT(BJ9/2) -> 3 | BL9: =MOD(BJ9,2) -> 0 | BM9: =+BN8 -> 6 | BN9: =INT(BM9/2) -> 3 | BO9: =MOD(BM9,2) -> 0 | BP9: =+BQ8 -> 2 | BQ9: =INT(BP9/2) -> 1 | BR9: =MOD(BP9,2) -> 0 | BS9: =+BT8 -> 6 | BT9: =INT(BS9/2) -> 3 | BU9: =MOD(BS9,2) -> 0 | BV9: =+BW8 -> 6 | BW9: =INT(BV9/2) -> 3 | BX9: =MOD(BV9,2) -> 0 | BY9: =+BZ8 -> 2 | BZ9: =INT(BY9/2) -> 1 | CA9: =MOD(BY9,2) -> 0 | CB9: =+CC8 -> 6 | CC9: =INT(CB9/2) -> 3 | CD9: =MOD(CB9,2) -> 0 | CE9: =+CF8 -> 6 | CF9: =INT(CE9/2) -> 3 | CG9: =MOD(CE9,2) -> 0 | CH9: =+CI8 -> 2 | CI9: =INT(CH9/2) -> 1 | CJ9: =MOD(CH9,2) -> 0 | CK9: =+CL8 -> 7 | CL9: =INT(CK9/2) -> 3 | CM9: =MOD(CK9,2) -> 1 | CN9: =+CO8 -> 6 | CO9: =INT(CN9/2) -> 3 | CP9: =MOD(CN9,2) -> 0 | CQ9: =+CR8 -> 6 | CR9: =INT(CQ9/2) -> 3 | CS9: =MOD(CQ9,2) -> 0 | CT9: =+CU8 -> 7 | CU9: =INT(CT9/2) -> 3 | CV9: =MOD(CT9,2) -> 1 | CW9: =+CX8 -> 6 | CX9: =INT(CW9/2) -> 3 | CY9: =MOD(CW9,2) -> 0 | CZ9: =+DA8 -> 7 | DA9: =INT(CZ9/2) -> 3 | DB9: =MOD(CZ9,2) -> 1 | DC9: =+DD8 -> 7 | DD9: =INT(DC9/2) -> 3 | DE9: =MOD(DC9,2) -> 1 | DF9: =+DG8 -> 6 | DG9: =INT(DF9/2) -> 3 | DH9: =MOD(DF9,2) -> 0 | DI9: =+DJ8 -> 6 | DJ9: =INT(DI9/2) -> 3 | DK9: =MOD(DI9,2) -> 0 | DL9: =+DM8 -> 6 | DM9: =INT(DL9/2) -> 3 | DN9: =MOD(DL9,2) -> 0 | DO9: =+DP8 -> 6 | DP9: =INT(DO9/2) -> 3 | DQ9: =MOD(DO9,2) -> 0 | DR9: =+DS8 -> 2 | DS9: =INT(DR9/2) -> 1 | DT9: =MOD(DR9,2) -> 0 | DU9: =+DV8 -> 6 | DV9: =INT(DU9/2) -> 3 | DW9: =MOD(DU9,2) -> 0 | DX9: =+DY8 -> 6 | DY9: =INT(DX9/2) -> 3 | DZ9: =MOD(DX9,2) -> 0 | EA9: =+EB8 -> 6 | EB9: =INT(EA9/2) -> 3 | EC9: =MOD(EA9,2) -> 0 | ED9: =+EE8 -> 6 | EE9: =INT(ED9/2) -> 3 | EF9: =MOD(ED9,2) -> 0 | EG9: =+EH8 -> 6 | EH9: =INT(EG9/2) -> 3 | EI9: =MOD(EG9,2) -> 0 | EJ9: =+EK8 -> 6 | EK9: =INT(EJ9/2) -> 3 | EL9: =MOD(EJ9,2) -> 0 | EM9: =+EN8 -> 6 | EN9: =INT(EM9/2) -> 3 | EO9: =MOD(EM9,2) -> 0
A10: =+A9+1 -> 6 | B10: a | C10: =+VLOOKUP(B10,Hoja2!$A:$E,5,0) -> 97 | D10: 97 | E10: 01100001 | F10: =+F9&$F$4&E10 -> 01000101 01101101 01110000 01100101 01111010 01100001 | H10: =+I9 -> 2 | I10: =INT(H10/2) -> 1 | J10: =MOD(H10,2) -> 0 | K10: =+L9 -> 3 | L10: =INT(K10/2) -> 1 | M10: =MOD(K10,2) -> 1 | N10: =+O9 -> 3 | O10: =INT(N10/2) -> 1 | P10: =MOD(N10,2) -> 1 | Q10: =+R9 -> 3 | R10: =INT(Q10/2) -> 1 | S10: =MOD(Q10,2) -> 1 | T10: =+U9 -> 3 | U10: =INT(T10/2) -> 1 | V10: =MOD(T10,2) -> 1 | W10: =+X9 -> 3 | X10: =INT(W10/2) -> 1 | Y10: =MOD(W10,2) -> 1 | Z10: =+AA9 -> 3 | AA10: =INT(Z10/2) -> 1 | AB10: =MOD(Z10,2) -> 1 | AC10: =+AD9 -> 3 | AD10: =INT(AC10/2) -> 1 | AE10: =MOD(AC10,2) -> 1 | AF10: =+AG9 -> 3 | AG10: =INT(AF10/2) -> 1 | AH10: =MOD(AF10,2) -> 1 | AI10: =+AJ9 -> 1 | AJ10: =INT(AI10/2) -> 0 | AK10: =MOD(AI10,2) -> 1 | AL10: =+AM9 -> 3 | AM10: =INT(AL10/2) -> 1 | AN10: =MOD(AL10,2) -> 1 | AO10: =+AP9 -> 3 | AP10: =INT(AO10/2) -> 1 | AQ10: =MOD(AO10,2) -> 1 | AR10: =+AS9 -> 1 | AS10: =INT(AR10/2) -> 0 | AT10: =MOD(AR10,2) -> 1 | AU10: =+AV9 -> 3 | AV10: =INT(AU10/2) -> 1 | AW10: =MOD(AU10,2) -> 1 | AX10: =+AY9 -> 3 | AY10: =INT(AX10/2) -> 1 | AZ10: =MOD(AX10,2) -> 1 | BA10: =+BB9 -> 3 | BB10: =INT(BA10/2) -> 1 | BC10: =MOD(BA10,2) -> 1 | BD10: =+BE9 -> 3 | BE10: =INT(BD10/2) -> 1 | BF10: =MOD(BD10,2) -> 1 | BG10: =+BH9 -> 3 | BH10: =INT(BG10/2) -> 1 | BI10: =MOD(BG10,2) -> 1 | BJ10: =+BK9 -> 3 | BK10: =INT(BJ10/2) -> 1 | BL10: =MOD(BJ10,2) -> 1 | BM10: =+BN9 -> 3 | BN10: =INT(BM10/2) -> 1 | BO10: =MOD(BM10,2) -> 1 | BP10: =+BQ9 -> 1 | BQ10: =INT(BP10/2) -> 0 | BR10: =MOD(BP10,2) -> 1 | BS10: =+BT9 -> 3 | BT10: =INT(BS10/2) -> 1 | BU10: =MOD(BS10,2) -> 1 | BV10: =+BW9 -> 3 | BW10: =INT(BV10/2) -> 1 | BX10: =MOD(BV10,2) -> 1 | BY10: =+BZ9 -> 1 | BZ10: =INT(BY10/2) -> 0 | CA10: =MOD(BY10,2) -> 1 | CB10: =+CC9 -> 3 | CC10: =INT(CB10/2) -> 1 | CD10: =MOD(CB10,2) -> 1 | CE10: =+CF9 -> 3 | CF10: =INT(CE10/2) -> 1 | CG10: =MOD(CE10,2) -> 1 | CH10: =+CI9 -> 1 | CI10: =INT(CH10/2) -> 0 | CJ10: =MOD(CH10,2) -> 1 | CK10: =+CL9 -> 3 | CL10: =INT(CK10/2) -> 1 | CM10: =MOD(CK10,2) -> 1 | CN10: =+CO9 -> 3 | CO10: =INT(CN10/2) -> 1 | CP10: =MOD(CN10,2) -> 1 | CQ10: =+CR9 -> 3 | CR10: =INT(CQ10/2) -> 1 | CS10: =MOD(CQ10,2) -> 1 | CT10: =+CU9 -> 3 | CU10: =INT(CT10/2) -> 1 | CV10: =MOD(CT10,2) -> 1 | CW10: =+CX9 -> 3 | CX10: =INT(CW10/2) -> 1 | CY10: =MOD(CW10,2) -> 1 | CZ10: =+DA9 -> 3 | DA10: =INT(CZ10/2) -> 1 | DB10: =MOD(CZ10,2) -> 1 | DC10: =+DD9 -> 3 | DD10: =INT(DC10/2) -> 1 | DE10: =MOD(DC10,2) -> 1 | DF10: =+DG9 -> 3 | DG10: =INT(DF10/2) -> 1 | DH10: =MOD(DF10,2) -> 1 | DI10: =+DJ9 -> 3 | DJ10: =INT(DI10/2) -> 1 | DK10: =MOD(DI10,2) -> 1 | DL10: =+DM9 -> 3 | DM10: =INT(DL10/2) -> 1 | DN10: =MOD(DL10,2) -> 1 | DO10: =+DP9 -> 3 | DP10: =INT(DO10/2) -> 1 | DQ10: =MOD(DO10,2) -> 1 | DR10: =+DS9 -> 1 | DS10: =INT(DR10/2) -> 0 | DT10: =MOD(DR10,2) -> 1 | DU10: =+DV9 -> 3 | DV10: =INT(DU10/2) -> 1 | DW10: =MOD(DU10,2) -> 1 | DX10: =+DY9 -> 3 | DY10: =INT(DX10/2) -> 1 | DZ10: =MOD(DX10,2) -> 1 | EA10: =+EB9 -> 3 | EB10: =INT(EA10/2) -> 1 | EC10: =MOD(EA10,2) -> 1 | ED10: =+EE9 -> 3 | EE10: =INT(ED10/2) -> 1 | EF10: =MOD(ED10,2) -> 1 | EG10: =+EH9 -> 3 | EH10: =INT(EG10/2) -> 1 | EI10: =MOD(EG10,2) -> 1 | EJ10: =+EK9 -> 3 | EK10: =INT(EJ10/2) -> 1 | EL10: =MOD(EJ10,2) -> 1 | EM10: =+EN9 -> 3 | EN10: =INT(EM10/2) -> 1 | EO10: =MOD(EM10,2) -> 1
A11: =+A10+1 -> 7 | B11: m | C11: =+VLOOKUP(B11,Hoja2!$A:$E,5,0) -> 109 | D11: 109 | E11: 01101101 | F11: =+F10&$F$4&E11 -> 01000101 01101101 01110000 01100101 01111010 01100001 01101101 | H11: =+I10 -> 1 | I11: =INT(H11/2) -> 0 | J11: =MOD(H11,2) -> 1 | K11: =+L10 -> 1 | L11: =INT(K11/2) -> 0 | M11: =MOD(K11,2) -> 1 | N11: =+O10 -> 1 | O11: =INT(N11/2) -> 0 | P11: =MOD(N11,2) -> 1 | Q11: =+R10 -> 1 | R11: =INT(Q11/2) -> 0 | S11: =MOD(Q11,2) -> 1 | T11: =+U10 -> 1 | U11: =INT(T11/2) -> 0 | V11: =MOD(T11,2) -> 1 | W11: =+X10 -> 1 | X11: =INT(W11/2) -> 0 | Y11: =MOD(W11,2) -> 1 | Z11: =+AA10 -> 1 | AA11: =INT(Z11/2) -> 0 | AB11: =MOD(Z11,2) -> 1 | AC11: =+AD10 -> 1 | AD11: =INT(AC11/2) -> 0 | AE11: =MOD(AC11,2) -> 1 | AF11: =+AG10 -> 1 | AG11: =INT(AF11/2) -> 0 | AH11: =MOD(AF11,2) -> 1 | AI11: =+AJ10 -> 0 | AJ11: =INT(AI11/2) -> 0 | AK11: =MOD(AI11,2) -> 0 | AL11: =+AM10 -> 1 | AM11: =INT(AL11/2) -> 0 | AN11: =MOD(AL11,2) -> 1 | AO11: =+AP10 -> 1 | AP11: =INT(AO11/2) -> 0 | AQ11: =MOD(AO11,2) -> 1 | AR11: =+AS10 -> 0 | AS11: =INT(AR11/2) -> 0 | AT11: =MOD(AR11,2) -> 0 | AU11: =+AV10 -> 1 | AV11: =INT(AU11/2) -> 0 | AW11: =MOD(AU11,2) -> 1 | AX11: =+AY10 -> 1 | AY11: =INT(AX11/2) -> 0 | AZ11: =MOD(AX11,2) -> 1 | BA11: =+BB10 -> 1 | BB11: =INT(BA11/2) -> 0 | BC11: =MOD(BA11,2) -> 1 | BD11: =+BE10 -> 1 | BE11: =INT(BD11/2) -> 0 | BF11: =MOD(BD11,2) -> 1 | BG11: =+BH10 -> 1 | BH11: =INT(BG11/2) -> 0 | BI11: =MOD(BG11,2) -> 1 | BJ11: =+BK10 -> 1 | BK11: =INT(BJ11/2) -> 0 | BL11: =MOD(BJ11,2) -> 1 | BM11: =+BN10 -> 1 | BN11: =INT(BM11/2) -> 0 | BO11: =MOD(BM11,2) -> 1 | BP11: =+BQ10 -> 0 | BQ11: =INT(BP11/2) -> 0 | BR11: =MOD(BP11,2) -> 0 | BS11: =+BT10 -> 1 | BT11: =INT(BS11/2) -> 0 | BU11: =MOD(BS11,2) -> 1 | BV11: =+BW10 -> 1 | BW11: =INT(BV11/2) -> 0 | BX11: =MOD(BV11,2) -> 1 | BY11: =+BZ10 -> 0 | BZ11: =INT(BY11/2) -> 0 | CA11: =MOD(BY11,2) -> 0 | CB11: =+CC10 -> 1 | CC11: =INT(CB11/2) -> 0 | CD11: =MOD(CB11,2) -> 1 | CE11: =+CF10 -> 1 | CF11: =INT(CE11/2) -> 0 | CG11: =MOD(CE11,2) -> 1 | CH11: =+CI10 -> 0 | CI11: =INT(CH11/2) -> 0 | CJ11: =MOD(CH11,2) -> 0 | CK11: =+CL10 -> 1 | CL11: =INT(CK11/2) -> 0 | CM11: =MOD(CK11,2) -> 1 | CN11: =+CO10 -> 1 | CO11: =INT(CN11/2) -> 0 | CP11: =MOD(CN11,2) -> 1 | CQ11: =+CR10 -> 1 | CR11: =INT(CQ11/2) -> 0 | CS11: =MOD(CQ11,2) -> 1 | CT11: =+CU10 -> 1 | CU11: =INT(CT11/2) -> 0 | CV11: =MOD(CT11,2) -> 1 | CW11: =+CX10 -> 1 | CX11: =INT(CW11/2) -> 0 | CY11: =MOD(CW11,2) -> 1 | CZ11: =+DA10 -> 1 | DA11: =INT(CZ11/2) -> 0 | DB11: =MOD(CZ11,2) -> 1 | DC11: =+DD10 -> 1 | DD11: =INT(DC11/2) -> 0 | DE11: =MOD(DC11,2) -> 1 | DF11: =+DG10 -> 1 | DG11: =INT(DF11/2) -> 0 | DH11: =MOD(DF11,2) -> 1 | DI11: =+DJ10 -> 1 | DJ11: =INT(DI11/2) -> 0 | DK11: =MOD(DI11,2) -> 1 | DL11: =+DM10 -> 1 | DM11: =INT(DL11/2) -> 0 | DN11: =MOD(DL11,2) -> 1 | DO11: =+DP10 -> 1 | DP11: =INT(DO11/2) -> 0 | DQ11: =MOD(DO11,2) -> 1 | DR11: =+DS10 -> 0 | DS11: =INT(DR11/2) -> 0 | DT11: =MOD(DR11,2) -> 0 | DU11: =+DV10 -> 1 | DV11: =INT(DU11/2) -> 0 | DW11: =MOD(DU11,2) -> 1 | DX11: =+DY10 -> 1 | DY11: =INT(DX11/2) -> 0 | DZ11: =MOD(DX11,2) -> 1 | EA11: =+EB10 -> 1 | EB11: =INT(EA11/2) -> 0 | EC11: =MOD(EA11,2) -> 1 | ED11: =+EE10 -> 1 | EE11: =INT(ED11/2) -> 0 | EF11: =MOD(ED11,2) -> 1 | EG11: =+EH10 -> 1 | EH11: =INT(EG11/2) -> 0 | EI11: =MOD(EG11,2) -> 1 | EJ11: =+EK10 -> 1 | EK11: =INT(EJ11/2) -> 0 | EL11: =MOD(EJ11,2) -> 1 | EM11: =+EN10 -> 1 | EN11: =INT(EM11/2) -> 0 | EO11: =MOD(EM11,2) -> 1
A12: =+A11+1 -> 8 | B12: o | C12: =+VLOOKUP(B12,Hoja2!$A:$E,5,0) -> 111 | D12: 111 | E12: 01101111 | F12: =+F11&$F$4&E12 -> 01000101 01101101 01110000 01100101 01111010 01100001 01101101 01101111
A13: =+A12+1 -> 9 | B13: s | C13: =+VLOOKUP(B13,Hoja2!$A:$E,5,0) -> 115 | D13: 115 | E13: 01110011 | F13: =+F12&$F$4&E13 -> 01000101 01101101 01110000 01100101 01111010 01100001 01101101 01101111 01110011 | H13: =+H4 -> E | J13: =0&J11&J10&J9&J8&J7&J6&J5 -> 01000101 | K13: =+K4 -> m | M13: =0&M11&M10&M9&M8&M7&M6&M5 -> 01101101 | N13: =+N4 -> p | P13: =0&P11&P10&P9&P8&P7&P6&P5 -> 01110000 | Q13: =+Q4 -> e | S13: =0&S11&S10&S9&S8&S7&S6&S5 -> 01100101 | T13: =+T4 -> z | V13: =0&V11&V10&V9&V8&V7&V6&V5 -> 01111010 | W13: =+W4 -> a | Y13: =0&Y11&Y10&Y9&Y8&Y7&Y6&Y5 -> 01100001 | Z13: =+Z4 -> m | AB13: =0&AB11&AB10&AB9&AB8&AB7&AB6&AB5 -> 01101101 | AC13: =+AC4 -> o | AE13: =0&AE11&AE10&AE9&AE8&AE7&AE6&AE5 -> 01101111 | AF13: =+AF4 -> s | AH13: =0&AH11&AH10&AH9&AH8&AH7&AH6&AH5 -> 01110011 | AI13: =+AI4 | AK13: =0&AK11&AK10&AK9&AK8&AK7&AK6&AK5 -> 00100000 | AL13: =+AL4 -> e | AN13: =0&AN11&AN10&AN9&AN8&AN7&AN6&AN5 -> 01100101 | AO13: =+AO4 -> l | AQ13: =0&AQ11&AQ10&AQ9&AQ8&AQ7&AQ6&AQ5 -> 01101100 | AR13: =+AR4 | AT13: =0&AT11&AT10&AT9&AT8&AT7&AT6&AT5 -> 00100000 | AU13: =+AU4 -> t | AW13: =0&AW11&AW10&AW9&AW8&AW7&AW6&AW5 -> 01110100 | AX13: =+AX4 -> e | AZ13: =0&AZ11&AZ10&AZ9&AZ8&AZ7&AZ6&AZ5 -> 01100101 | BA13: =+BA4 -> c | BC13: =0&BC11&BC10&BC9&BC8&BC7&BC6&BC5 -> 01100011 | BD13: =+BD4 -> n | BF13: =0&BF11&BF10&BF9&BF8&BF7&BF6&BF5 -> 01101110 | BG13: =+BG4 -> i | BI13: =0&BI11&BI10&BI9&BI8&BI7&BI6&BI5 -> 01101001 | BJ13: =+BJ4 -> c | BL13: =0&BL11&BL10&BL9&BL8&BL7&BL6&BL5 -> 01100011 | BM13: =+BM4 -> o | BO13: =0&BO11&BO10&BO9&BO8&BO7&BO6&BO5 -> 01101111 | BP13: =+BP4 | BR13: =0&BR11&BR10&BR9&BR8&BR7&BR6&BR5 -> 00100000 | BS13: =+BS4 -> e | BU13: =0&BU11&BU10&BU9&BU8&BU7&BU6&BU5 -> 01100101 | BV13: =+BV4 -> n | BX13: =0&BX11&BX10&BX9&BX8&BX7&BX6&BX5 -> 01101110 | BY13: =+BY4 | CA13: =0&CA11&CA10&CA9&CA8&CA7&CA6&CA5 -> 00100000 | CB13: =+CB4 -> l | CD13: =0&CD11&CD10&CD9&CD8&CD7&CD6&CD5 -> 01101100 | CE13: =+CE4 -> a | CG13: =0&CG11&CG10&CG9&CG8&CG7&CG6&CG5 -> 01100001 | CH13: =+CH4 | CJ13: =0&CJ11&CJ10&CJ9&CJ8&CJ7&CJ6&CJ5 -> 00100000 | CK13: =+CK4 -> u | CM13: =0&CM11&CM10&CM9&CM8&CM7&CM6&CM5 -> 01110101 | CN13: =+CN4 -> n | CP13: =0&CP11&CP10&CP9&CP8&CP7&CP6&CP5 -> 01101110 | CQ13: =+CQ4 -> i | CS13: =0&CS11&CS10&CS9&CS8&CS7&CS6&CS5 -> 01101001 | CT13: =+CT4 -> v | CV13: =0&CV11&CV10&CV9&CV8&CV7&CV6&CV5 -> 01110110 | CW13: =+CW4 -> e | CY13: =0&CY11&CY10&CY9&CY8&CY7&CY6&CY5 -> 01100101 | CZ13: =+CZ4 -> r | DB13: =0&DB11&DB10&DB9&DB8&DB7&DB6&DB5 -> 01110010 | DC13: =+DC4 -> s | DE13: =0&DE11&DE10&DE9&DE8&DE7&DE6&DE5 -> 01110011 | DF13: =+DF4 -> i | DH13: =0&DH11&DH10&DH9&DH8&DH7&DH6&DH5 -> 01101001 | DI13: =+DI4 -> d | DK13: =0&DK11&DK10&DK9&DK8&DK7&DK6&DK5 -> 01100100 | DL13: =+DL4 -> a | DN13: =0&DN11&DN10&DN9&DN8&DN7&DN6&DN5 -> 01100001 | DO13: =+DO4 -> d | DQ13: =0&DQ11&DQ10&DQ9&DQ8&DQ7&DQ6&DQ5 -> 01100100 | DR13: =+DR4 | DT13: =0&DT11&DT10&DT9&DT8&DT7&DT6&DT5 -> 00100000 | DU13: =+DU4 -> g | DW13: =0&DW11&DW10&DW9&DW8&DW7&DW6&DW5 -> 01100111 | DX13: =+DX4 -> a | DZ13: =0&DZ11&DZ10&DZ9&DZ8&DZ7&DZ6&DZ5 -> 01100001 | EA13: =+EA4 -> l | EC13: =0&EC11&EC10&EC9&EC8&EC7&EC6&EC5 -> 01101100 | ED13: =+ED4 -> i | EF13: =0&EF11&EF10&EF9&EF8&EF7&EF6&EF5 -> 01101001 | EG13: =+EG4 -> l | EI13: =0&EI11&EI10&EI9&EI8&EI7&EI6&EI5 -> 01101100 | EJ13: =+EJ4 -> e | EL13: =0&EL11&EL10&EL9&EL8&EL7&EL6&EL5 -> 01100101 | EM13: =+EM4 -> o | EO13: =0&EO11&EO10&EO9&EO8&EO7&EO6&EO5 -> 01101111
A14: =+A13+1 -> 10 | C14: =+VLOOKUP(B14,Hoja2!$A:$E,5,0) -> 32 | D14: 32 | E14: 00100000 | F14: =+F13&$F$4&E14 -> 01000101 01101101 01110000 01100101 01111010 01100001 01101101 01101111 01110011 00100000
A15: =+A14+1 -> 11 | B15: e | C15: =+VLOOKUP(B15,Hoja2!$A:$E,5,0) -> 101 | D15: 101 | E15: 01100101 | F15: =+F14&$F$4&E15 -> 01000101 01101101 01110000 01100101 01111010 01100001 01101101 01101111 01110011 00100000 01100101
A16: =+A15+1 -> 12 | B16: l | C16: =+VLOOKUP(B16,Hoja2!$A:$E,5,0) -> 108 | D16: 108 | E16: 01101100 | F16: =+F15&$F$4&E16 -> 01000101 01101101 01110000 01100101 01111010 01100001 01101101 01101111 01110011 00100000 01100101 01101100 | H16: E | J16: 01000101 | K16: m | M16: 01101101 | N16: p | P16: 01110000 | Q16: e | S16: 01000101 | T16: z | V16: 01111010 | W16: a | Y16: 01100001 | Z16: m | AB16: 01101101 | AC16: o | AE16: 01101111 | AF16: s | AH16: 01110011 | AK16: 00100000 | AL16: e | AN16: 01000101 | AO16: l | AQ16: 01101100 | AT16: 00100000 | AU16: t | AW16: 01110100 | AX16: é | AZ16: 01001001 | BA16: c | BC16: 01100011 | BD16: n | BF16: 01101110 | BG16: i | BI16: 01101001 | BJ16: c | BL16: 01100011 | BM16: o | BO16: 01101111 | BR16: 00100000 | BS16: e | BU16: 01000101 | BV16: n | BX16: 01101110 | CA16: 00100000 | CB16: l | CD16: 01101100 | CE16: a | CG16: 01100001 | CJ16: 00100000 | CK16: u | CM16: 01110101 | CN16: n | CP16: 01101110 | CQ16: i | CS16: 01101001 | CT16: v | CV16: 01110110 | CW16: e | CY16: 01000101 | CZ16: r | DB16: 01110010 | DC16: s | DE16: 01110011 | DF16: i | DH16: 01101001 | DI16: d | DK16: 01100100 | DL16: a | DN16: 01100001 | DO16: d | DQ16: 01100100 | DT16: 00100000 | DU16: g | DW16: 01100111 | DX16: a | DZ16: 01100001 | EA16: l | EC16: 01101100 | ED16: i | EF16: 01101001 | EG16: l | EI16: 01101100 | EJ16: e | EL16: 01000101 | EM16: o | EO16: 01101111
A17: =+A16+1 -> 13 | C17: =+VLOOKUP(B17,Hoja2!$A:$E,5,0) -> 32 | D17: 32 | E17: 00100000 | F17: =+F16&$F$4&E17 -> 01000101 01101101 01110000 01100101 01111010 01100001 01101101 01101111 01110011 00100000 01100101 01101100 00100000
A18: =+A17+1 -> 14 | B18: t | C18: =+VLOOKUP(B18,Hoja2!$A:$E,5,0) -> 116 | D18: 116 | E18: 01110100 | F18: =+F17&$F$4&E18 -> 01000101 01101101 01110000 01100101 01111010 01100001 01101101 01101111 01110011 00100000 01100101 01101100 00100000 01110100
A19: =+A18+1 -> 15 | B19: e | C19: =+VLOOKUP(B19,Hoja2!$A:$E,5,0) -> 101 | D19: 101 | E19: 01100101 | F19: =+F18&$F$4&E19 -> 01000101 01101101 01110000 01100101 01111010 01100001 01101101 01101111 01110011 00100000 01100101 01101100 00100000 01110100 01100101
A20: =+A19+1 -> 16 | B20: c | C20: =+VLOOKUP(B20,Hoja2!$A:$E,5,0) -> 99 | D20: 99 | E20: 01100011 | F20: =+F19&$F$4&E20 -> 01000101 01101101 01110000 01100101 01111010 01100001 01101101 01101111 01110011 00100000 01100101 01101100 00100000 01110100 01100101 01100011
A21: =+A20+1 -> 17 | B21: n | C21: =+VLOOKUP(B21,Hoja2!$A:$E,5,0) -> 110 | D21: 110 | E21: 01101110 | F21: =+F20&$F$4&E21 -> 01000101 01101101 01110000 01100101 01111010 01100001 01101101 01101111 01110011 00100000 01100101 01101100 00100000 01110100 01100101 01100011 01101110
A22: =+A21+1 -> 18 | B22: i | C22: =+VLOOKUP(B22,Hoja2!$A:$E,5,0) -> 105 | D22: 105 | E22: 01101001 | F22: =+F21&$F$4&E22 -> 01000101 01101101 01110000 01100101 01111010 01100001 01101101 01101111 01110011 00100000 01100101 01101100 00100000 01110100 01100101 01100011 01101110 01101001
A23: =+A22+1 -> 19 | B23: c | C23: =+VLOOKUP(B23,Hoja2!$A:$E,5,0) -> 99 | D23: 99 | E23: 01100011 | F23: =+F22&$F$4&E23 -> 01000101 01101101 01110000 01100101 01111010 01100001 01101101 01101111 01110011 00100000 01100101 01101100 00100000 01110100 01100101 01100011 01101110 01101001 01100011
A24: =+A23+1 -> 20 | B24: o | C24: =+VLOOKUP(B24,Hoja2!$A:$E,5,0) -> 111 | D24: 111 | E24: 01101111 | F24: =+F23&$F$4&E24 -> 01000101 01101101 01110000 01100101 01111010 01100001 01101101 01101111 01110011 00100000 01100101 01101100 00100000 01110100 01100101 01100011 01101110 01101001 01100011 01101111
A25: =+A24+1 -> 21 | C25: =+VLOOKUP(B25,Hoja2!$A:$E,5,0) -> 32 | D25: 32 | E25: 00100000 | F25: =+F24&$F$4&E25 -> 01000101 01101101 01110000 01100101 01111010 01100001 01101101 01101111 01110011 00100000 01100101 01101100 00100000 01110100 01100101 01100011 01101110 01101001 01100011 01101111 00100000
A26: =+A25+1 -> 22 | B26: e | C26: =+VLOOKUP(B26,Hoja2!$A:$E,5,0) -> 101 | D26: 101 | E26: 01100101 | F26: =+F25&$F$4&E26 -> 01000101 01101101 01110000 01100101 01111010 01100001 01101101 01101111 01110011 00100000 01100101 01101100 00100000 01110100 01100101 01100011 01101110 01101001 01100011 01101111 00100000 01100101
A27: =+A26+1 -> 23 | B27: n | C27: =+VLOOKUP(B27,Hoja2!$A:$E,5,0) -> 110 | D27: 110 | E27: 01101110 | F27: =+F26&$F$4&E27 -> 01000101 01101101 01110000 01100101 01111010 01100001 01101101 01101111 01110011 00100000 01100101 01101100 00100000 01110100 01100101 01100011 01101110 01101001 01100011 01101111 00100000 01100101 01101110
A28: =+A27+1 -> 24 | C28: =+VLOOKUP(B28,Hoja2!$A:$E,5,0) -> 32 | D28: 32 | E28: 00100000 | F28: =+F27&$F$4&E28 -> 01000101 01101101 01110000 01100101 01111010 01100001 01101101 01101111 01110011 00100000 01100101 01101100 00100000 01110100 01100101 01100011 01101110 01101001 01100011 01101111 00100000 01100101 01101110 00100000
A29: =+A28+1 -> 25 | B29: l | C29: =+VLOOKUP(B29,Hoja2!$A:$E,5,0) -> 108 | D29: 108 | E29: 01101100 | F29: =+F28&$F$4&E29 -> 01000101 01101101 01110000 01100101 01111010 01100001 01101101 01101111 01110011 00100000 01100101 01101100 00100000 01110100 01100101 01100011 01101110 01101001 01100011 01101111 00100000 01100101 01101110 00100000 01101100
A30: =+A29+1 -> 26 | B30: a | C30: =+VLOOKUP(B30,Hoja2!$A:$E,5,0) -> 97 | D30: 97 | E30: 01100001 | F30: =+F29&$F$4&E30 -> 01000101 01101101 01110000 01100101 01111010 01100001 01101101 01101111 01110011 00100000 01100101 01101100 00100000 01110100 01100101 01100011 01101110 01101001 01100011 01101111 00100000 01100101 01101110 00100000 01101100 01100001
A31: =+A30+1 -> 27 | C31: =+VLOOKUP(B31,Hoja2!$A:$E,5,0) -> 32 | D31: 32 | E31: 00100000 | F31: =+F30&$F$4&E31 -> 01000101 01101101 01110000 01100101 01111010 01100001 01101101 01101111 01110011 00100000 01100101 01101100 00100000 01110100 01100101 01100011 01101110 01101001 01100011 01101111 00100000 01100101 01101110 00100000 01101100 01100001 00100000
A32: =+A31+1 -> 28 | B32: u | C32: =+VLOOKUP(B32,Hoja2!$A:$E,5,0) -> 117 | D32: 117 | E32: 01110101 | F32: =+F31&$F$4&E32 -> 01000101 01101101 01110000 01100101 01111010 01100001 01101101 01101111 01110011 00100000 01100101 01101100 00100000 01110100 01100101 01100011 01101110 01101001 01100011 01101111 00100000 01100101 01101110 00100000 01101100 01100001 00100000 01110101
A33: =+A32+1 -> 29 | B33: n | C33: =+VLOOKUP(B33,Hoja2!$A:$E,5,0) -> 110 | D33: 110 | E33: 01101110 | F33: =+F32&$F$4&E33 -> 01000101 01101101 01110000 01100101 01111010 01100001 01101101 01101111 01110011 00100000 01100101 01101100 00100000 01110100 01100101 01100011 01101110 01101001 01100011 01101111 00100000 01100101 01101110 00100000 01101100 01100001 00100000 01110101 01101110
A34: =+A33+1 -> 30 | B34: i | C34: =+VLOOKUP(B34,Hoja2!$A:$E,5,0) -> 105 | D34: 105 | E34: 01101001 | F34: =+F33&$F$4&E34 -> 01000101 01101101 01110000 01100101 01111010 01100001 01101101 01101111 01110011 00100000 01100101 01101100 00100000 01110100 01100101 01100011 01101110 01101001 01100011 01101111 00100000 01100101 01101110 00100000 01101100 01100001 00100000 01110101 01101110 01101001
A35: =+A34+1 -> 31 | B35: v | C35: =+VLOOKUP(B35,Hoja2!$A:$E,5,0) -> 118 | D35: 118 | E35: 01110110 | F35: =+F34&$F$4&E35 -> 01000101 01101101 01110000 01100101 01111010 01100001 01101101 01101111 01110011 00100000 01100101 01101100 00100000 01110100 01100101 01100011 01101110 01101001 01100011 01101111 00100000 01100101 01101110 00100000 01101100 01100001 00100000 01110101 01101110 01101001 01110110
A36: =+A35+1 -> 32 | B36: e | C36: =+VLOOKUP(B36,Hoja2!$A:$E,5,0) -> 101 | D36: 101 | E36: 01100101 | F36: =+F35&$F$4&E36 -> 01000101 01101101 01110000 01100101 01111010 01100001 01101101 01101111 01110011 00100000 01100101 01101100 00100000 01110100 01100101 01100011 01101110 01101001 01100011 01101111 00100000 01100101 01101110 00100000 01101100 01100001 00100000 01110101 01101110 01101001 01110110 01100101
A37: =+A36+1 -> 33 | B37: r | C37: =+VLOOKUP(B37,Hoja2!$A:$E,5,0) -> 114 | D37: 114 | E37: 01110010 | F37: =+F36&$F$4&E37 -> 01000101 01101101 01110000 01100101 01111010 01100001 01101101 01101111 01110011 00100000 01100101 01101100 00100000 01110100 01100101 01100011 01101110 01101001 01100011 01101111 00100000 01100101 01101110 00100000 01101100 01100001 00100000 01110101 01101110 01101001 01110110 01100101 01110010
A38: =+A37+1 -> 34 | B38: s | C38: =+VLOOKUP(B38,Hoja2!$A:$E,5,0) -> 115 | D38: 115 | E38: 01110011 | F38: =+F37&$F$4&E38 -> 01000101 01101101 01110000 01100101 01111010 01100001 01101101 01101111 01110011 00100000 01100101 01101100 00100000 01110100 01100101 01100011 01101110 01101001 01100011 01101111 00100000 01100101 01101110 00100000 01101100 01100001 00100000 01110101 01101110 01101001 01110110 01100101 01110010 01110011
A39: =+A38+1 -> 35 | B39: i | C39: =+VLOOKUP(B39,Hoja2!$A:$E,5,0) -> 105 | D39: 105 | E39: 01101001 | F39: =+F38&$F$4&E39 -> 01000101 01101101 01110000 01100101 01111010 01100001 01101101 01101111 01110011 00100000 01100101 01101100 00100000 01110100 01100101 01100011 01101110 01101001 01100011 01101111 00100000 01100101 01101110 00100000 01101100 01100001 00100000 01110101 01101110 01101001 01110110 01100101 01110010 01110011 01101001
A40: =+A39+1 -> 36 | B40: d | C40: =+VLOOKUP(B40,Hoja2!$A:$E,5,0) -> 100 | D40: 100 | E40: 01100100 | F40: =+F39&$F$4&E40 -> 01000101 01101101 01110000 01100101 01111010 01100001 01101101 01101111 01110011 00100000 01100101 01101100 00100000 01110100 01100101 01100011 01101110 01101001 01100011 01101111 00100000 01100101 01101110 00100000 01101100 01100001 00100000 01110101 01101110 01101001 01110110 01100101 01110010 01110011 01101001 01100100
A41: =+A40+1 -> 37 | B41: a | C41: =+VLOOKUP(B41,Hoja2!$A:$E,5,0) -> 97 | D41: 97 | E41: 01100001 | F41: =+F40&$F$4&E41 -> 01000101 01101101 01110000 01100101 01111010 01100001 01101101 01101111 01110011 00100000 01100101 01101100 00100000 01110100 01100101 01100011 01101110 01101001 01100011 01101111 00100000 01100101 01101110 00100000 01101100 01100001 00100000 01110101 01101110 01101001 01110110 01100101 01110010 01110011 01101001 01100100 01100001
...

Sheet 2
B2: Empezamo el técnico en la universidad galileo
H3: 1 | K3: =+H3+1 -> 2 | N3: =+K3+1 -> 3 | Q3: =+N3+1 -> 4 | T3: =+Q3+1 -> 5 | W3: =+T3+1 -> 6 | Z3: =+W3+1 -> 7 | AC3: =+Z3+1 -> 8 | AF3: =+AC3+1 -> 9 | AI3: =+AF3+1 -> 10 | AL3: =+AI3+1 -> 11 | AO3: =+AL3+1 -> 12 | AR3: =+AO3+1 -> 13
H4: J | I4: Cociente | J4: Residuo | K4: =+VLOOKUP(K3,$A:$B,2,0) -> e | L4: Cociente | M4: Residuo | N4: =+VLOOKUP(N3,$A:$B,2,0) -> s | O4: Cociente | P4: Residuo | Q4: =+VLOOKUP(Q3,$A:$B,2,0) -> u | R4: Cociente | S4: Residuo | T4: =+VLOOKUP(T3,$A:$B,2,0) -> s | U4: Cociente | V4: Residuo | W4: =+VLOOKUP(W3,$A:$B,2,0) | X4: Cociente | Y4: Residuo | Z4: =+VLOOKUP(Z3,$A:$B,2,0) -> S | AA4: Cociente | AB4: Residuo | AC4: =+VLOOKUP(AC3,$A:$B,2,0) -> a | AD4: Cociente | AE4: Residuo | AF4: =+VLOOKUP(AF3,$A:$B,2,0) -> m | AG4: Cociente | AH4: Residuo | AI4: =+VLOOKUP(AI3,$A:$B,2,0) -> a | AJ4: Cociente | AK4: Residuo | AL4: y | AM4: Cociente | AN4: Residuo | AO4: =+VLOOKUP(AO3,$A:$B,2,0) -> o | AP4: Cociente | AQ4: Residuo | AR4: =+VLOOKUP(AR3,$A:$B,2,0) -> a | AS4: Cociente | AT4: Residuo
A5: 1 | B5: J | C5: =+VLOOKUP(B5,Hoja2!$G:$K,5,0) -> 74 | D5: 74 | E5: =+J13 -> 01001010 | F5: =+E5 -> 01001010 | H5: 74 | I5: =INT(H5/2) -> 37 | J5: =MOD(H5,2) -> 0 | K5: =+VLOOKUP(K4,$B:$D,3,0) -> 101 | L5: =INT(K5/2) -> 50 | M5: =MOD(K5,2) -> 1 | N5: =+VLOOKUP(N4,$B:$D,3,0) -> 115 | O5: =INT(N5/2) -> 57 | P5: =MOD(N5,2) -> 1 | Q5: =+VLOOKUP(Q4,$B:$D,3,0) -> 117 | R5: =INT(Q5/2) -> 58 | S5: =MOD(Q5,2) -> 1 | T5: =+VLOOKUP(T4,$B:$D,3,0) -> 115 | U5: =INT(T5/2) -> 57 | V5: =MOD(T5,2) -> 1 | W5: =+VLOOKUP(W4,$B:$D,3,0) -> 32 | X5: =INT(W5/2) -> 16 | Y5: =MOD(W5,2) -> 0 | Z5: 83 | AA5: =INT(Z5/2) -> 41 | AB5: =MOD(Z5,2) -> 1 | AC5: =+VLOOKUP(AC4,$B:$D,3,0) -> 97 | AD5: =INT(AC5/2) -> 48 | AE5: =MOD(AC5,2) -> 1 | AF5: =+VLOOKUP(AF4,$B:$D,3,0) -> 109 | AG5: =INT(AF5/2) -> 54 | AH5: =MOD(AF5,2) -> 1 | AI5: =+VLOOKUP(AI4,$B:$D,3,0) -> 97 | AJ5: =INT(AI5/2) -> 48 | AK5: =MOD(AI5,2) -> 1 | AL5: =+VLOOKUP(AL4,$B:$D,3,0) -> 121 | AM5: =INT(AL5/2) -> 60 | AN5: =MOD(AL5,2) -> 1 | AO5: =+VLOOKUP(AO4,$B:$D,3,0) -> 111 | AP5: =INT(AO5/2) -> 55 | AQ5: =MOD(AO5,2) -> 1 | AR5: =+VLOOKUP(AR4,$B:$D,3,0) -> 97 | AS5: =INT(AR5/2) -> 48 | AT5: =MOD(AR5,2) -> 1
A6: =+A5+1 -> 2 | B6: e | C6: =+VLOOKUP(B6,Hoja2!$A:$E,5,0) -> 101 | D6: 101 | E6: =+M13 -> 01100101 | F6: =+F5&$F$4&E6 -> 01001010 01100101 | H6: =+I5 -> 37 | I6: =INT(H6/2) -> 18 | J6: =MOD(H6,2) -> 1 | K6: =+L5 -> 50 | L6: =INT(K6/2) -> 25 | M6: =MOD(K6,2) -> 0 | N6: =+O5 -> 57 | O6: =INT(N6/2) -> 28 | P6: =MOD(N6,2) -> 1 | Q6: =+R5 -> 58 | R6: =INT(Q6/2) -> 29 | S6: =MOD(Q6,2) -> 0 | T6: =+U5 -> 57 | U6: =INT(T6/2) -> 28 | V6: =MOD(T6,2) -> 1 | W6: =+X5 -> 16 | X6: =INT(W6/2) -> 8 | Y6: =MOD(W6,2) -> 0 | Z6: =+AA5 -> 41 | AA6: =INT(Z6/2) -> 20 | AB6: =MOD(Z6,2) -> 1 | AC6: =+AD5 -> 48 | AD6: =INT(AC6/2) -> 24 | AE6: =MOD(AC6,2) -> 0 | AF6: =+AG5 -> 54 | AG6: =INT(AF6/2) -> 27 | AH6: =MOD(AF6,2) -> 0 | AI6: =+AJ5 -> 48 | AJ6: =INT(AI6/2) -> 24 | AK6: =MOD(AI6,2) -> 0 | AL6: =+AM5 -> 60 | AM6: =INT(AL6/2) -> 30 | AN6: =MOD(AL6,2) -> 0 | AO6: =+AP5 -> 55 | AP6: =INT(AO6/2) -> 27 | AQ6: =MOD(AO6,2) -> 1 | AR6: =+AS5 -> 48 | AS6: =INT(AR6/2) -> 24 | AT6: =MOD(AR6,2) -> 0
A7: =+A6+1 -> 3 | B7: s | C7: =+VLOOKUP(B7,Hoja2!$A:$E,5,0) -> 115 | D7: 115 | E7: =+P13 -> 01110011 | F7: =+F6&$F$4&E7 -> 01001010 01100101 01110011 | H7: =+I6 -> 18 | I7: =INT(H7/2) -> 9 | J7: =MOD(H7,2) -> 0 | K7: =+L6 -> 25 | L7: =INT(K7/2) -> 12 | M7: =MOD(K7,2) -> 1 | N7: =+O6 -> 28 | O7: =INT(N7/2) -> 14 | P7: =MOD(N7,2) -> 0 | Q7: =+R6 -> 29 | R7: =INT(Q7/2) -> 14 | S7: =MOD(Q7,2) -> 1 | T7: =+U6 -> 28 | U7: =INT(T7/2) -> 14 | V7: =MOD(T7,2) -> 0 | W7: =+X6 -> 8 | X7: =INT(W7/2) -> 4 | Y7: =MOD(W7,2) -> 0 | Z7: =+AA6 -> 20 | AA7: =INT(Z7/2) -> 10 | AB7: =MOD(Z7,2) -> 0 | AC7: =+AD6 -> 24 | AD7: =INT(AC7/2) -> 12 | AE7: =MOD(AC7,2) -> 0 | AF7: =+AG6 -> 27 | AG7: =INT(AF7/2) -> 13 | AH7: =MOD(AF7,2) -> 1 | AI7: =+AJ6 -> 24 | AJ7: =INT(AI7/2) -> 12 | AK7: =MOD(AI7,2) -> 0 | AL7: =+AM6 -> 30 | AM7: =INT(AL7/2) -> 15 | AN7: =MOD(AL7,2) -> 0 | AO7: =+AP6 -> 27 | AP7: =INT(AO7/2) -> 13 | AQ7: =MOD(AO7,2) -> 1 | AR7: =+AS6 -> 24 | AS7: =INT(AR7/2) -> 12 | AT7: =MOD(AR7,2) -> 0
A8: =+A7+1 -> 4 | B8: u | C8: =+VLOOKUP(B8,Hoja2!$A:$E,5,0) -> 117 | D8: 117 | E8: =+S13 -> 01110101 | F8: =+F7&$F$4&E8 -> 01001010 01100101 01110011 01110101 | H8: =+I7 -> 9 | I8: =INT(H8/2) -> 4 | J8: =MOD(H8,2) -> 1 | K8: =+L7 -> 12 | L8: =INT(K8/2) -> 6 | M8: =MOD(K8,2) -> 0 | N8: =+O7 -> 14 | O8: =INT(N8/2) -> 7 | P8: =MOD(N8,2) -> 0 | Q8: =+R7 -> 14 | R8: =INT(Q8/2) -> 7 | S8: =MOD(Q8,2) -> 0 | T8: =+U7 -> 14 | U8: =INT(T8/2) -> 7 | V8: =MOD(T8,2) -> 0 | W8: =+X7 -> 4 | X8: =INT(W8/2) -> 2 | Y8: =MOD(W8,2) -> 0 | Z8: =+AA7 -> 10 | AA8: =INT(Z8/2) -> 5 | AB8: =MOD(Z8,2) -> 0 | AC8: =+AD7 -> 12 | AD8: =INT(AC8/2) -> 6 | AE8: =MOD(AC8,2) -> 0 | AF8: =+AG7 -> 13 | AG8: =INT(AF8/2) -> 6 | AH8: =MOD(AF8,2) -> 1 | AI8: =+AJ7 -> 12 | AJ8: =INT(AI8/2) -> 6 | AK8: =MOD(AI8,2) -> 0 | AL8: =+AM7 -> 15 | AM8: =INT(AL8/2) -> 7 | AN8: =MOD(AL8,2) -> 1 | AO8: =+AP7 -> 13 | AP8: =INT(AO8/2) -> 6 | AQ8: =MOD(AO8,2) -> 1 | AR8: =+AS7 -> 12 | AS8: =INT(AR8/2) -> 6 | AT8: =MOD(AR8,2) -> 0
A9: =+A8+1 -> 5 | B9: s | C9: 115 | D9: 115 | E9: =+V13 -> 01110011 | F9: =+F8&$F$4&E9 -> 01001010 01100101 01110011 01110101 01110011 | H9: =+I8 -> 4 | I9: =INT(H9/2) -> 2 | J9: =MOD(H9,2) -> 0 | K9: =+L8 -> 6 | L9: =INT(K9/2) -> 3 | M9: =MOD(K9,2) -> 0 | N9: =+O8 -> 7 | O9: =INT(N9/2) -> 3 | P9: =MOD(N9,2) -> 1 | Q9: =+R8 -> 7 | R9: =INT(Q9/2) -> 3 | S9: =MOD(Q9,2) -> 1 | T9: =+U8 -> 7 | U9: =INT(T9/2) -> 3 | V9: =MOD(T9,2) -> 1 | W9: =+X8 -> 2 | X9: =INT(W9/2) -> 1 | Y9: =MOD(W9,2) -> 0 | Z9: =+AA8 -> 5 | AA9: =INT(Z9/2) -> 2 | AB9: =MOD(Z9,2) -> 1 | AC9: =+AD8 -> 6 | AD9: =INT(AC9/2) -> 3 | AE9: =MOD(AC9,2) -> 0 | AF9: =+AG8 -> 6 | AG9: =INT(AF9/2) -> 3 | AH9: =MOD(AF9,2) -> 0 | AI9: =+AJ8 -> 6 | AJ9: =INT(AI9/2) -> 3 | AK9: =MOD(AI9,2) -> 0 | AL9: =+AM8 -> 7 | AM9: =INT(AL9/2) -> 3 | AN9: =MOD(AL9,2) -> 1 | AO9: =+AP8 -> 6 | AP9: =INT(AO9/2) -> 3 | AQ9: =MOD(AO9,2) -> 0 | AR9: =+AS8 -> 6 | AS9: =INT(AR9/2) -> 3 | AT9: =MOD(AR9,2) -> 0
A10: =+A9+1 -> 6 | C10: =+VLOOKUP(B10,Hoja2!$A:$E,5,0) -> 32 | D10: 32 | E10: =+Y13 -> 00100000 | F10: =+F9&$F$4&E10 -> 01001010 01100101 01110011 01110101 01110011 00100000 | H10: =+I9 -> 2 | I10: =INT(H10/2) -> 1 | J10: =MOD(H10,2) -> 0 | K10: =+L9 -> 3 | L10: =INT(K10/2) -> 1 | M10: =MOD(K10,2) -> 1 | N10: =+O9 -> 3 | O10: =INT(N10/2) -> 1 | P10: =MOD(N10,2) -> 1 | Q10: =+R9 -> 3 | R10: =INT(Q10/2) -> 1 | S10: =MOD(Q10,2) -> 1 | T10: =+U9 -> 3 | U10: =INT(T10/2) -> 1 | V10: =MOD(T10,2) -> 1 | W10: =+X9 -> 1 | X10: =INT(W10/2) -> 0 | Y10: =MOD(W10,2) -> 1 | Z10: =+AA9 -> 2 | AA10: =INT(Z10/2) -> 1 | AB10: =MOD(Z10,2) -> 0 | AC10: =+AD9 -> 3 | AD10: =INT(AC10/2) -> 1 | AE10: =MOD(AC10,2) -> 1 | AF10: =+AG9 -> 3 | AG10: =INT(AF10/2) -> 1 | AH10: =MOD(AF10,2) -> 1 | AI10: =+AJ9 -> 3 | AJ10: =INT(AI10/2) -> 1 | AK10: =MOD(AI10,2) -> 1 | AL10: =+AM9 -> 3 | AM10: =INT(AL10/2) -> 1 | AN10: =MOD(AL10,2) -> 1 | AO10: =+AP9 -> 3 | AP10: =INT(AO10/2) -> 1 | AQ10: =MOD(AO10,2) -> 1 | AR10: =+AS9 -> 3 | AS10: =INT(AR10/2) -> 1 | AT10: =MOD(AR10,2) -> 1
A11: =+A10+1 -> 7 | B11: S | C11: =+VLOOKUP(B11,Hoja2!$G:$K,5,0) -> 83 | D11: 83 | E11: =+AB13 -> 01010011 | F11: =+F10&$F$4&E11 -> 01001010 01100101 01110011 01110101 01110011 00100000 01010011 | H11: =+I10 -> 1 | I11: =INT(H11/2) -> 0 | J11: =MOD(H11,2) -> 1 | K11: =+L10 -> 1 | L11: =INT(K11/2) -> 0 | M11: =MOD(K11,2) -> 1 | N11: =+O10 -> 1 | O11: =INT(N11/2) -> 0 | P11: =MOD(N11,2) -> 1 | Q11: =+R10 -> 1 | R11: =INT(Q11/2) -> 0 | S11: =MOD(Q11,2) -> 1 | T11: =+U10 -> 1 | U11: =INT(T11/2) -> 0 | V11: =MOD(T11,2) -> 1 | W11: =+X10 -> 0 | X11: =INT(W11/2) -> 0 | Y11: =MOD(W11,2) -> 0 | Z11: =+AA10 -> 1 | AA11: =INT(Z11/2) -> 0 | AB11: =MOD(Z11,2) -> 1 | AC11: =+AD10 -> 1 | AD11: =INT(AC11/2) -> 0 | AE11: =MOD(AC11,2) -> 1 | AF11: =+AG10 -> 1 | AG11: =INT(AF11/2) -> 0 | AH11: =MOD(AF11,2) -> 1 | AI11: =+AJ10 -> 1 | AJ11: =INT(AI11/2) -> 0 | AK11: =MOD(AI11,2) -> 1 | AL11: =+AM10 -> 1 | AM11: =INT(AL11/2) -> 0 | AN11: =MOD(AL11,2) -> 1 | AO11: =+AP10 -> 1 | AP11: =INT(AO11/2) -> 0 | AQ11: =MOD(AO11,2) -> 1 | AR11: =+AS10 -> 1 | AS11: =INT(AR11/2) -> 0 | AT11: =MOD(AR11,2) -> 1
A12: =+A11+1 -> 8 | B12: a | C12: =+VLOOKUP(B12,Hoja2!$A:$E,5,0) -> 97 | D12: 97 | E12: =+AE13 -> 01100001 | F12: =+F11&$F$4&E12 -> 01001010 01100101 01110011 01110101 01110011 00100000 01010011 01100001
A13: =+A12+1 -> 9 | B13: m | C13: =+VLOOKUP(B13,Hoja2!$A:$E,5,0) -> 109 | D13: 109 | E13: =+AH13 -> 01101101 | F13: =+F12&$F$4&E13 -> 01001010 01100101 01110011 01110101 01110011 00100000 01010011 01100001 01101101 | H13: =+H4 -> J | J13: =0&J11&J10&J9&J8&J7&J6&J5 -> 01001010 | K13: =+K4 -> e | M13: =0&M11&M10&M9&M8&M7&M6&M5 -> 01100101 | N13: =+N4 -> s | P13: =0&P11&P10&P9&P8&P7&P6&P5 -> 01110011 | Q13: =+Q4 -> u | S13: =0&S11&S10&S9&S8&S7&S6&S5 -> 01110101 | T13: =+T4 -> s | V13: =0&V11&V10&V9&V8&V7&V6&V5 -> 01110011 | W13: =+W4 | Y13: =0&Y11&Y10&Y9&Y8&Y7&Y6&Y5 -> 00100000 | Z13: =+Z4 -> S | AB13: =0&AB11&AB10&AB9&AB8&AB7&AB6&AB5 -> 01010011 | AC13: =+AC4 -> a | AE13: =0&AE11&AE10&AE9&AE8&AE7&AE6&AE5 -> 01100001 | AF13: =+AF4 -> m | AH13: =0&AH11&AH10&AH9&AH8&AH7&AH6&AH5 -> 01101101 | AI13: =+AI4 -> a | AK13: =0&AK11&AK10&AK9&AK8&AK7&AK6&AK5 -> 01100001 | AL13: =+AL4 -> y | AN13: =0&AN11&AN10&AN9&AN8&AN7&AN6&AN5 -> 01111001 | AO13: =+AO4 -> o | AQ13: =0&AQ11&AQ10&AQ9&AQ8&AQ7&AQ6&AQ5 -> 01101111 | AR13: =+AR4 -> a | AT13: =0&AT11&AT10&AT9&AT8&AT7&AT6&AT5 -> 01100001
A14: =+A13+1 -> 10 | B14: a | C14: =+VLOOKUP(B14,Hoja2!$A:$E,5,0) -> 97 | D14: 97 | E14: =+AK13 -> 01100001 | F14: =+F13&$F$4&E14 -> 01001010 01100101 01110011 01110101 01110011 00100000 01010011 01100001 01101101 01100001
A15: =+A14+1 -> 11 | B15: y | C15: =+VLOOKUP(B15,Hoja2!$A:$E,5,0) -> 121 | D15: 121 | E15: =+AN13 -> 01111001 | F15: =+F14&$F$4&E15 -> 01001010 01100101 01110011 01110101 01110011 00100000 01010011 01100001 01101101 01100001 01111001
A16: =+A15+1 -> 12 | B16: o | C16: =+VLOOKUP(B16,Hoja2!$A:$E,5,0) -> 111 | D16: 111 | E16: =+AQ13 -> 01101111 | F16: =+F15&$F$4&E16 -> 01001010 01100101 01110011 01110101 01110011 00100000 01010011 01100001 01101101 01100001 01111001 01101111
A17: =+A16+1 -> 13 | B17: a | C17: =+VLOOKUP(B17,Hoja2!$A:$E,5,0) -> 97 | D17: 97 | E17: =+AT13 -> 01100001 | F17: =+F16&$F$4&E17 -> 01001010 01100101 01110011 01110101 01110011 00100000 01010011 01100001 01101101 01100001 01111001 01101111 01100001 | H17: J | J17: 01000101 | K17: e | M17: 01101101 | N17: s | P17: 01110000 | Q17: u | S17: 01100101 | T17: s | V17: 01110000 | Y17: 01100001 | Z17: S | AB17: 01110000 | AC17: a | AE17: 01101111 | AF17: m | AH17: 01110011 | AI17: a | AK17: 01101111 | AL17: y | AN17: 01100101 | AO17: o | AQ17: 01101100 | AR17: a | AT17: 01101111

Sheet Hoja2
B1: Space | C1: ASCII Value of ‘Space’ is 32 | E1: 32 | G1: A | H1: Uppercase A | I1: ASCII Value of ‘Uppercase A’ is 65 | K1: 65
A2: ! | B2: Exclamation mark | C2: ASCII Value of ‘Exclamation mark’ is 33 | E2: 33 | G2: B | H2: Uppercase B | I2: ASCII Value of ‘Uppercase B’ is 66 | K2: 66
A3: “ | B3: Double quotes (or speech marks) | C3: ASCII Value of ‘Double quotes (or speech marks)’ is 34 | E3: 34 | G3: C | H3: Uppercase C | I3: ASCII Value of ‘Uppercase C’ is 67 | K3: 67
A4: # | B4: Number | C4: ASCII Value of ‘Number’ is 35 | E4: 35 | G4: D | H4: Uppercase D | I4: ASCII Value of ‘Uppercase D’ is 68 | K4: 68
A5: $ | B5: Dollar | C5: ASCII Value of ‘Dollar’ is 36 | E5: 36 | G5: E | H5: Uppercase E | I5: ASCII Value of ‘Uppercase E’ is 69 | K5: 69
A6: % | B6: Per cent sign | C6: ASCII Value of ‘Per cent sign’ is 37 | E6: 37 | G6: F | H6: Uppercase F | I6: ASCII Value of ‘Uppercase F’ is 70 | K6: 70
A7: & | B7: Ampersand | C7: ASCII Value of ‘Ampersand’ is 38 | E7: 38 | G7: G | H7: Uppercase G | I7: ASCII Value of ‘Uppercase G’ is 71 | K7: 71
A8: ‘ | B8: Single quote | C8: ASCII Value of ‘Single quote’ is 39 | E8: 39 | G8: H | H8: Uppercase H | I8: ASCII Value of ‘Uppercase H’ is 72 | K8: 72
A9: ( | B9: Open parenthesis (or open bracket) | C9: ASCII Value of ‘Open parenthesis (or open bracket)’ is 40 | E9: 40 | G9: I | H9: Uppercase I | I9: ASCII Value of ‘Uppercase I’ is 73 | K9: 73
A10: ) | B10: Close parenthesis (or close bracket) | C10: ASCII Value of ‘Close parenthesis (or close bracket)’ is 41 | E10: 41 | G10: J | H10: Uppercase J | I10: ASCII Value of ‘Uppercase J’ is 74 | K10: 74
A11: * | B11: Asterisk | C11: ASCII Value of ‘Asterisk’ is 42 | E11: 42 | G11: K | H11: Uppercase K | I11: ASCII Value of ‘Uppercase K’ is 75 | K11: 75
A12: + | B12: Plus | C12: ASCII Value of ‘Plus’ is 43 | E12: 43 | G12: L | H12: Uppercase L | I12: ASCII Value of ‘Uppercase L’ is 76 | K12: 76
A13: , | B13: Comma | C13: ASCII Value of ‘Comma’ is 44 | E13: 44 | G13: M | H13: Uppercase M | I13: ASCII Value of ‘Uppercase M’ is 77 | K13: 77
... A16: / | B16: Slash or divide | C16: ASCII Value of ‘Slash or divide’ is 47 | E16: 47 | G16: P | H16: Uppercase P | I16: ASCII Value of ‘Uppercase P’ is 80 | K16: 80
A17: 0 | B17: Zero | C17: ASCII Value of ‘Zero’ is 48 | E17: 48 | G17: Q | H17: Uppercase Q | I17: ASCII Value of ‘Uppercase Q’ is 81 | K17: 81
A18: 1 | B18: One | C18: ASCII Value of ‘One’ is 49 | E18: 49 | G18: R | H18: Uppercase R | I18: ASCII Value of ‘Uppercase R’ is 82 | K18: 82
A19: 2 | B19: Two | C19: ASCII Value of ‘Two’ is 50 | E19: 50 | G19: S | H19: Uppercase S | I19: ASCII Value of ‘Uppercase S’ is 83 | K19: 83
A20: 3 | B20: Three | C20: ASCII Value of ‘Three’ is 51 | E20: 51 | G20: T | H20: Uppercase T | I20: ASCII Value of ‘Uppercase T’ is 84 | K20: 84
A21: 4 | B21: Four | C21: ASCII Value of ‘Four’ is 52 | E21: 52 | G21: U | H21: Uppercase U | I21: ASCII Value of ‘Uppercase U’ is 85 | K21: 85
A22: 5 | B22: Five | C22: ASCII Value of ‘Five’ is 53 | E22: 53 | G22: V | H22: Uppercase V | I22: ASCII Value of ‘Uppercase V’ is 86 | K22: 86
A23: 6 | B23: Six | C23: ASCII Value of ‘Six’ is 54 | E23: 54 | G23: W | H23: Uppercase W | I23: ASCII Value of ‘Uppercase W’ is 87 | K23: 87
A24: 7 | B24: Seven | C24: ASCII Value of ‘Seven’ is 55 | E24: 55 | G24: X | H24: Uppercase X | I24: ASCII Value of ‘Uppercase X’ is 88 | K24: 88
A25: 8 | B25: Eight | C25: ASCII Value of ‘Eight’ is 56 | E25: 56 | G25: Y | H25: Uppercase Y | I25: ASCII Value of ‘Uppercase Y’ is 89 | K25: 89
A26: 9 | B26: Nine | C26: ASCII Value of ‘Nine’ is 57 | E26: 57 | G26: Z | H26: Uppercase Z | I26: ASCII Value of ‘Uppercase Z’ is 90 | K26: 90
A27: : | B27: Colon | C27: ASCII Value of ‘Colon’ is 58 | E27: 58
A28: ; | B28: Semicolon | C28: ASCII Value of ‘Semicolon’ is 59 | E28: 59
A29: < | B29: Less than (or open angled bracket) | C29: ASCII Value of ‘Less than (or open angled bracket)’ is 60 | E29: 60
A30: = | B30: Equals | C30: ASCII Value of ‘Equals’ is 61 | E30: 61
A31: > | B31: Greater than (or close angled bracket) | C31: ASCII Value of ‘Greater than (or close angled bracket)’ is 62 | E31: 62
A32: ? | B32: Question mark | C32: ASCII Value of ‘Question mark’ is 63 | E32: 63
A33: @ | B33: At symbol | C33: ASCII Value of ‘At symbol’ is 64 | E33: 64
A35: [ | B35: Opening bracket | C35: ASCII Value of ‘Opening bracket’ is 91 | E35: 91
A36: \ | B36: Backslash | C36: ASCII Value of ‘Backslash’ is 92 | E36: 92
A37: ] | B37: Closing bracket | C37: ASCII Value of ‘Closing bracket’ is 93 | E37: 93
A38: ^ | B38: Caret – circumflex | C38: ASCII Value of ‘Caret – circumflex’ is 94 | E38: 94
A39: _ | B39: Underscore | C39: ASCII Value of ‘Underscore’ is 95 | E39: 95
... A83: Œ | B83: Latin capital ligature OE | C83: ASCII Value of ‘Latin capital ligature OE’ is 140 | E83: 140
A84:  | B84: 0 | C84: ASCII Value of ‘0’ is 141 | E84: 141
A85: Ž | B85: Latin capital letter Z with caron | C85: ASCII Value of ‘Latin capital letter Z with caron’ is 142 | E85: 142
A86:  | B86: 0 | C86: ASCII Value of ‘0’ is 143 | E86: 143
...
